Workbook
Name Y: #REF!

Sheet 수입검사 대장
C3: 불합격: | D3: =COUNTIF(X7:X182,"RE")/COUNTA(X7:X82) -> 0 | E3: 검사수: | F3: =SUM(I7:I82) -> 33 | G3: 불량수: | H3: =SUM(H7:H82) -> 3 | I3: 불량%: | J3: =H3/F3*100 -> 9.0909091
A4: No. | B4: 일자 | C4: 업체 명 | D4: 적용 Model | E4: 규격 | F4: LOT 수 | G4: 입고 수량 | H4: 불량 LOT 수 | I4: 검사 LOT 수 | J4: 불량율(%) | K4: 불량 유형 | W4: 검사자 | X4: 판정 | Y4: 비고(처리)
K6: Pinion SPEC | L6: 나사산 | M6: Pitch | N6: 탭 | O6: O.C | P6: Dirty | Q6: 변색 | R6: 소음 | S6: 찍힘 | T6: S/C | U6: 이물 | V6: 기타
A7: 1 | B7: 45296 | C7: 메탈 팩토리 | D7: Linear servo | E7: 선삭 lead screw 외 | F7: 5 | H7: 0 | I7: 5 | J7: =IFERROR(H7/I7,"0") -> 0 | X7: AC
A8: 2 | B8: 45300 | C8: 미래 ENG | D8: Linear servo | E8: Hinge, Hinge base | F8: 2 | H8: 0 | I8: 2 | J8: =IFERROR(H8/I8,"0") -> 0 | X8: AC
A9: 3 | B9: 45324 | C9: JMT | D9: Linear servo | E9: Accessory | F9: 1 | H9: 0 | I9: 1 | J9: =IFERROR(H9/I9,"0") -> 0 | X9: AC
A10: 4 | B10: 45327 | C10: 메탈 팩토리 | D10: Linear servo | E10: Lead screw 45mm 1줄 외 | F10: 3 | H10: 2 | I10: 3 | J10: =IFERROR(H10/I10,"0") -> 0.66666667 | X10: 합격 lot
A11: 7 | B11: 45350 | C11: JMT | D11: Linear servo | E11: Connector wire IR-1119521 | F11: 1 | H11: 0 | I11: 1 | J11: =IFERROR(H11/I11,"0") -> 0 | X11: AC
A12: 8 | B12: 45362 | C12: 미래 ENG | D12: Linear servo | E12: PT Top Case외 1종 | F12: 2 | H12: 0 | I12: 2 | J12: =IFERROR(H12/I12,"0") -> 0 | X12: AC
A13: 9 | B13: 45363 | C13: 미래 ENG | D13: Linear servo | E13: Output Gear외 1종 | F13: 2 | H13: 0 | I13: 2 | J13: =IFERROR(H13/I13,"0") -> 0 | X13: AC
A14: 10 | B14: 45364 | C14: 미래 ENG | D14: Linear servo | E14: Gear box top 외 8종 | F14: 9 | H14: 0 | I14: 9 | J14: =IFERROR(H14/I14,"0") -> 0 | X14: AC
A15: 11 | B15: 45376 | C15: 메탈 팩토리 | D15: Linear servo | E15: 인청동 Insert 외 1종 | F15: 2 | H15: 1 | I15: 2 | J15: =IFERROR(H15/I15,"0") -> 0.5 | X15: 합격 lot
A16: 12 | B16: 45383 | C16: 메탈 팩토리 | D16: Linear servo | E16: 이구스 Insert 60mm외 2종 | F16: 3 | H16: 0 | I16: 3 | J16: =IFERROR(H16/I16,"0") -> 0 | X16: AC
A17: 13 | B17: 45390 | C17: 미래 ENG | D17: Linear servo | E17: Output Gear외 2종 | F17: 3 | H17: 0 | I17: 3 | J17: =IFERROR(H17/I17,"0") -> 0 | X17: AC
A18: 14 | J18: =IFERROR(H18/I18,"0") -> 0
A19: 15 | J19: =IFERROR(H19/I19,"0") -> 0
A20: 16 | J20: =IFERROR(H20/I20,"0") -> 0
A21: 17 | J21: =IFERROR(H21/I21,"0") -> 0
A22: 18 | J22: =IFERROR(H22/I22,"0") -> 0
A23: 19 | J23: =IFERROR(H23/I23,"0") -> 0
A24: 20 | J24: =IFERROR(H24/I24,"0") -> 0
A25: 21 | J25: =IFERROR(H25/I25,"0") -> 0
A26: 22 | J26: =IFERROR(H26/I26,"0") -> 0
A27: 23 | J27: =IFERROR(H27/I27,"0") -> 0
A28: 24 | J28: =IFERROR(H28/I28,"0") -> 0
A29: 25 | J29: =IFERROR(H29/I29,"0") -> 0
... A82: 78 | J82: =IFERROR(H82/I82,"0") -> 0
C83: =IFERROR(VLOOKUP(E83,#REF!,7,0),"") | D83: =IFERROR(VLOOKUP(E83,#REF!,6,0),"") | G83: =SUM(G7:G82) -> 0 | H83: =SUM(H7:H82) -> 3 | I83: =SUM(I7:I82) -> 33 | J83: =IFERROR((H83/I83),"0") -> 0.090909091 | K83: =SUM(K7:K82) -> 0 | L83: =SUM(L7:L82) -> 0 | M83: =SUM(M7:M82) -> 0 | N83: =SUM(N7:N82) -> 0 | O83: =SUM(O7:O82) -> 0 | P83: =SUM(P7:P82) -> 0 | Q83: =SUM(Q7:Q82) -> 0 | R83: =SUM(R7:R82) -> 0 | ... V83: =SUM(V7:V82) -> 0
X85: LOT 수 | Y85: =COUNTA(X7:X82) -> 11
X86: 합격 | Y86: =COUNTIF(X7:X82,"AC") -> 9
X87: 불합격 | Y87: =COUNTIF(X7:X82,"RE") -> 0
X88: 불합격율 | Y88: =IFERROR(Y87/Y85*100,"0") -> 0

Sheet 수입검사
A1: 업체 별 불량 [%]
A2: 업체 명 | B2: 항목 | C2: 1 | D2: 2 | E2: 3 | F2: 4 | G2: 5 | H2: 6 | I2: 7 | J2: 8 | K2: 9 | L2: 10 | M2: 11 | N2: 12 | O2: 합계
A3: CNB | B3: 입고수 | C3: =[1]검사현황!$B$3 -> 1000 | D3: =[1]검사현황!$C$3 -> 0 | E3: =[1]검사현황!$D$3 -> 5000 | F3: =[1]검사현황!$E$3 -> 5000 | G3: =[1]검사현황!$F$3 -> 2000 | H3: =[1]검사현황!$G$3 -> 0 | I3: =[1]검사현황!$H$3 -> 1000 | J3: =[1]검사현황!$I$3 -> 1000 | K3: =[1]검사현황!$J$3 -> 9000 | L3: =[1]검사현황!$K$3 -> 1000 | M3: =[1]검사현황!$L$3 -> 0 | N3: =[1]검사현황!$M$3 -> 2000 | O3: =SUM(C3:N3) -> 27000
B4: 불량 % | C4: =[1]검사현황!$B$6 -> 0 | D4: =[1]검사현황!$C$6 -> 0 | E4: =[1]검사현황!$D$6 -> 0 | F4: =[1]검사현황!$E$6 -> 0 | G4: =[1]검사현황!$F$6 -> 0 | H4: =[1]검사현황!$G$6 -> 0 | I4: =[1]검사현황!$H$6 -> 0 | J4: =[1]검사현황!$I$6 -> 0 | K4: =[1]검사현황!$J$6 -> 0 | L4: =[1]검사현황!$K$6 -> 0 | M4: =[1]검사현황!$L$6 -> 0 | N4: =[1]검사현황!$M$6 -> 3.3333333 | O4: =[1]검사현황!$N$6 -> 0.21551724
A5: 미래 ENG | B5: 입고수 | C5: =[2]검사현황!$B$3 -> 0 | D5: =[2]검사현황!$C$3 -> 5772 | E5: =[2]검사현황!$D$3 -> 8438 | F5: =[2]검사현황!$E$3 -> 64000 | G5: =[2]검사현황!$F$3 -> 0 | H5: =[2]검사현황!$G$3 -> 6000 | I5: =[2]검사현황!$H$3 -> 0 | J5: =[2]검사현황!$I$3 -> 14200 | K5: =[2]검사현황!$J$3 -> 36440 | L5: =[2]검사현황!$K$3 -> 0 | M5: =[2]검사현황!$L$3 -> 0 | N5: =[2]검사현황!$M$3 -> 870 | O5: =SUM(C5:N5) -> 135720
B6: 불량 % | C6: =[2]검사현황!$B$6 -> 0 | D6: =[2]검사현황!$C$6 -> 0.65789474 | E6: =[2]검사현황!$D$6 -> 0 | F6: =[2]검사현황!$E$6 -> 4.6728972 | G6: =[2]검사현황!$F$6 -> 0 | H6: =[2]검사현황!$G$6 -> 0 | I6: =[2]검사현황!$H$6 -> 0 | J6: =[2]검사현황!$I$6 -> 0 | K6: =[2]검사현황!$J$6 -> 0 | L6: =[2]검사현황!$K$6 -> 0 | M6: =[2]검사현황!$L$6 -> 0 | N6: =[2]검사현황!$M$6 -> 0 | O6: =[2]검사현황!$N$6 -> 1.7931034
A7: 메탈 팩토리 | B7: 입고수 | C7: =[3]검사현황!$B$3 -> 15939 | D7: =[3]검사현황!$C$3 -> 7360 | E7: =[3]검사현황!$D$3 -> 5020 | F7: =[3]검사현황!$E$3 -> 3000 | G7: =[3]검사현황!$F$3 -> 10000 | H7: =[3]검사현황!$G$3 -> 4000 | I7: =[3]검사현황!$H$3 -> 12000 | J7: =[3]검사현황!$I$3 -> 9000 | K7: =[3]검사현황!$J$3 -> 4020 | L7: =[3]검사현황!$K$3 -> 8162 | M7: =[3]검사현황!$L$3 -> 3097 | N7: =[3]검사현황!$M$3 -> 2810 | O7: =SUM(C7:N7) -> 84408
B8: 불량 % | C8: =[3]검사현황!$B$6 -> 0 | D8: =[3]검사현황!$C$6 -> 20 | E8: =[3]검사현황!$D$6 -> 69.230769 | F8: =[3]검사현황!$E$6 -> 5 | G8: =[3]검사현황!$F$6 -> 0 | H8: =[3]검사현황!$G$6 -> 0 | I8: =[3]검사현황!$H$6 -> 5.6872038 | J8: =[3]검사현황!$I$6 -> 0 | K8: =[3]검사현황!$J$6 -> 0 | L8: =[3]검사현황!$K$6 -> 0 | M8: =[3]검사현황!$L$6 -> 0 | N8: =[3]검사현황!$M$6 -> 12.5 | O8: =[3]검사현황!$N$6 -> 7.5466595
A9: 전진로링 | B9: 입고수 | C9: =[4]검사현황!$B$3 -> 938 | D9: =[4]검사현황!$C$3 -> 0 | E9: =[4]검사현황!$D$3 -> 996 | F9: =[4]검사현황!$E$3 -> 0 | G9: =[4]검사현황!$F$3 -> 2000 | H9: =[4]검사현황!$G$3 -> 0 | I9: =[4]검사현황!$H$3 -> 2000 | J9: =[4]검사현황!$I$3 -> 1510 | K9: =[4]검사현황!$J$3 -> 500 | L9: =[4]검사현황!$K$3 -> 982 | M9: =[4]검사현황!$L$3 -> 0 | N9: =[4]검사현황!$M$3 -> 2491 | O9: =SUM(C9:N9) -> 11417
B10: 불량 % | C10: =[4]검사현황!$B$6 -> 0 | D10: =[4]검사현황!$C$6 -> 0 | E10: =[4]검사현황!$D$6 -> 0 | F10: =[4]검사현황!$E$6 -> 0 | G10: =[4]검사현황!$F$6 -> 0 | H10: =[4]검사현황!$G$6 -> 0 | I10: =[4]검사현황!$H$6 -> 0 | J10: =[4]검사현황!$I$6 -> 0 | K10: =[4]검사현황!$J$6 -> 0 | L10: =[4]검사현황!$K$6 -> 0 | M10: =[4]검사현황!$L$6 -> 0 | N10: =[4]검사현황!$M$6 -> 0 | O10: =[4]검사현황!$N$6 -> 0
A11: 시대전자 | B11: 입고수 | C11: =[5]검사현황!$B$3 -> 0 | D11: =[5]검사현황!$C$3 -> 0 | E11: =[5]검사현황!$D$3 -> 4000 | F11: =[5]검사현황!$E$3 -> 3260 | G11: =[5]검사현황!$F$3 -> 0 | H11: =[5]검사현황!$G$3 -> 0 | I11: =[5]검사현황!$H$3 -> 0 | J11: =[5]검사현황!$H$3 -> 0 | K11: =[5]검사현황!$J$3 -> 3000 | L11: =[5]검사현황!$K$3 -> 500 | M11: =[5]검사현황!$L$3 -> 0 | N11: =[5]검사현황!$M$3 -> 0 | O11: =SUM(C11:N11) -> 10760
B12: 불량 % | C12: =[5]검사현황!$B$6 -> 0 | D12: =[5]검사현황!$C$6 -> 0 | E12: =[5]검사현황!$D$6 -> 0 | F12: =[5]검사현황!$E$6 -> 0 | G12: =[5]검사현황!$F$6 -> 0 | H12: =[5]검사현황!$G$6 -> 0 | I12: =[5]검사현황!$H$6 -> 0 | J12: =[5]검사현황!$H$6 -> 0 | K12: =[5]검사현황!$J$6 -> 0 | L12: =[5]검사현황!$K$6 -> 0 | M12: =[5]검사현황!$L$6 -> 0 | N12: =[5]검사현황!$M$6 -> 0 | O12: =[5]검사현황!$N$6 -> 0
A13: 일흥테크 | B13: 입고수 | C13: =[6]검사현황!$B$3 -> 0 | D13: =[6]검사현황!$C$3 -> 0 | E13: =[6]검사현황!$D$3 -> 2500 | F13: =[6]검사현황!$E$3 -> 0 | G13: =[6]검사현황!$F$3 -> 0 | H13: =[6]검사현황!$G$3 -> 0 | I13: =[6]검사현황!$H$3 -> 0 | J13: =[6]검사현황!$I$3 -> 0 | K13: =[6]검사현황!$J$3 -> 0 | L13: =[6]검사현황!$K$3 -> 0 | M13: =[6]검사현황!$L$3 -> 1000 | N13: =[6]검사현황!$M$3 -> 0 | O13: =SUM(C13:N13) -> 3500
B14: 불량 % | C14: =[6]검사현황!$B$6 -> 0 | D14: =[6]검사현황!$C$6 -> 0 | E14: =[6]검사현황!$D$6 -> 20 | F14: =[6]검사현황!$E$6 -> 0 | G14: =[6]검사현황!$F$6 -> 0 | H14: =[6]검사현황!$G$6 -> 0 | I14: =[6]검사현황!$H$6 -> 0 | J14: =[6]검사현황!$I$6 -> 0 | K14: =[6]검사현황!$J$6 -> 0 | L14: =[6]검사현황!$K$6 -> 0 | M14: =[6]검사현황!$L$6 -> 0 | N14: =[6]검사현황!$M$6 -> 0 | O14: =[6]검사현황!$N$6 -> 14.285714
A15: 시너지테크 | B15: 입고수 | C15: =[7]검사현황!$B$3 -> 0 | D15: =[7]검사현황!$C$3 -> 0 | E15: =[7]검사현황!$D$3 -> 0 | F15: =[7]검사현황!$E$3 -> 3820 | G15: =[7]검사현황!$F$3 -> 0 | H15: =[7]검사현황!$G$3 -> 2117 | I15: =[7]검사현황!$H$3 -> 1000 | J15: =[7]검사현황!$I$3 -> 0 | K15: =[7]검사현황!$J$3 -> 3000 | L15: =[7]검사현황!$K$3 -> 0 | M15: =[7]검사현황!$L$3 -> 0 | N15: =[7]검사현황!$M$3 -> 400 | O15: =SUM(C15:N15) -> 10337
B16: 불량 % | C16: =[7]검사현황!$B$6 -> 0 | D16: =[7]검사현황!$C$6 -> 0 | E16: =[7]검사현황!$D$6 -> 0 | F16: =[7]검사현황!$E$6 -> 1.6990291 | G16: =[7]검사현황!$F$6 -> 0 | H16: =[7]검사현황!$G$6 -> 1.0152284 | I16: =[7]검사현황!$H$6 -> 0 | J16: =[7]검사현황!$I$6 -> 0 | K16: =[7]검사현황!$J$6 -> 0 | L16: =[7]검사현황!$K$6 -> 0 | M16: =[7]검사현황!$L$6 -> 0 | N16: =[7]검사현황!$M$6 -> 0 | O16: =[7]검사현황!$N$6 -> 1.0356732
A17: 천호금속 | B17: 입고수 | C17: =[8]검사현황!$B$3 -> 2500 | D17: =[8]검사현황!$C$3 -> 0 | E17: =[8]검사현황!$D$3 -> 0 | F17: =[8]검사현황!$E$3 -> 0 | G17: =[8]검사현황!$F$3 -> 0 | H17: =[8]검사현황!$G$3 -> 0 | I17: =[8]검사현황!$H$3 -> 0 | J17: =[8]검사현황!$I$3 -> 0 | K17: =[8]검사현황!$J$3 -> 0 | L17: =[8]검사현황!$K$3 -> 0 | M17: =[8]검사현황!$L$3 -> 0 | N17: =[8]검사현황!$M$3 -> 0 | O17: =SUM(C17:N17) -> 2500
B18: 불량 % | C18: =[8]검사현황!$B$6 -> 0 | D18: =[8]검사현황!$C$6 -> 0 | E18: =[8]검사현황!$D$6 -> 0 | F18: =[8]검사현황!$E$6 -> 0 | G18: =[8]검사현황!$F$6 -> 0 | H18: =[8]검사현황!$G$6 -> 0 | I18: =[8]검사현황!$H$6 -> 0 | J18: =[8]검사현황!$I$6 -> 0 | K18: =[8]검사현황!$J$6 -> 0 | L18: =[8]검사현황!$K$6 -> 0 | M18: =[8]검사현황!$L$6 -> 0 | N18: =[8]검사현황!$M$6 -> 0 | O18: =[8]검사현황!$N$6 -> 0
A19: 태광시스템 | B19: 입고수 | O19: =SUM(C19:N19) -> 0
B20: 불량 %
A21: 유니프로 | B21: 입고수 | C21: =[9]검사현황!$B$3 -> 50000 | D21: =[9]검사현황!$C$3 -> 152000 | E21: =[9]검사현황!$D$3 -> 0 | F21: =[9]검사현황!$E$3 -> 0 | G21: =[9]검사현황!$F$3 -> 0 | H21: =[9]검사현황!$G$3 -> 0 | I21: =[9]검사현황!$H$3 -> 0 | J21: =[9]검사현황!$I$3 -> 0 | K21: =[9]검사현황!$J$3 -> 100000 | L21: =[9]검사현황!$K$3 -> 0 | M21: =[9]검사현황!$L$3 -> 0 | N21: =[9]검사현황!$M$3 -> 0 | O21: =[9]검사현황!$N$3 -> 302000
B22: 불량 % | C22: =[9]검사현황!$B$6 -> 0 | D22: =[9]검사현황!$C$6 -> 0 | E22: =[9]검사현황!$D$6 -> 0 | F22: =[9]검사현황!$E$6 -> 0 | G22: =[9]검사현황!$F$6 -> 0 | H22: =[9]검사현황!$G$6 -> 0 | I22: =[9]검사현황!$H$6 -> 0 | J22: =[9]검사현황!$I$6 -> 0 | K22: =[9]검사현황!$J$6 -> 0 | L22: =[9]검사현황!$K$6 -> 0 | M22: =[9]검사현황!$L$6 -> 0 | N22: =[9]검사현황!$M$6 -> 0 | O22: =[9]검사현황!$N$6 -> 0
A23: JMT | B23: 입고수 | C23: =[10]검사현황!$B$3 -> 0 | D23: =[10]검사현황!$C$3 -> 17066 | E23: =[10]검사현황!$D$3 -> 3000 | F23: =[10]검사현황!$E$3 -> 0 | G23: =[10]검사현황!$F$3 -> 0 | H23: =[10]검사현황!$G$3 -> 0 | I23: =[10]검사현황!$H$3 -> 4000 | J23: =[10]검사현황!$I$3 -> 0 | K23: =[10]검사현황!$J$3 -> 0 | L23: =[10]검사현황!$K$3 -> 0 | M23: =[10]검사현황!$L$3 -> 0 | N23: =[10]검사현황!$M$3 -> 0 | O23: =SUM(C23:N23) -> 24066
B24: 불량 % | C24: =[10]검사현황!$B$6 -> 0 | D24: =[10]검사현황!$C$6 -> 0 | E24: =[10]검사현황!$D$6 -> 0 | F24: =[10]검사현황!$E$6 -> 0 | G24: =[10]검사현황!$F$6 -> 0 | H24: =[10]검사현황!$G$6 -> 0 | I24: =[10]검사현황!$H$6 -> 0 | J24: =[10]검사현황!$I$6 -> 0 | K24: =[10]검사현황!$J$6 -> 0 | L24: =[10]검사현황!$K$6 -> 0 | M24: =[10]검사현황!$L$6 -> 0 | N24: =[10]검사현황!$M$6 -> 0 | O24: =[10]검사현황!$N$6 -> 0
A25: 갑텍 | B25: 입고수 | C25: =[11]검사현황!$B$3 -> 0 | D25: =[11]검사현황!$C$3 -> 0 | E25: =[11]검사현황!$D$3 -> 0 | F25: =[11]검사현황!$E$3 -> 0 | G25: =[11]검사현황!$F$3 -> 0 | H25: =[11]검사현황!$G$3 -> 0 | I25: =[11]검사현황!$H$3 -> 0 | J25: =[11]검사현황!$I$3 -> 0 | K25: =[11]검사현황!$J$3 -> 28000 | L25: =[11]검사현황!$K$3 -> 0 | M25: =[11]검사현황!$L$3 -> 0 | N25: =[11]검사현황!$M$3 -> 0 | O25: =SUM(C25:N25) -> 28000
B26: 불량 % | C26: =[11]검사현황!$B$6 -> 0 | D26: =[11]검사현황!$C$6 -> 0 | E26: =[11]검사현황!$D$6 -> 0 | F26: =[11]검사현황!$E$6 -> 0 | G26: =[11]검사현황!$F$6 -> 0 | H26: =[11]검사현황!$G$6 -> 0 | I26: =[11]검사현황!$H$6 -> 0 | J26: =[11]검사현황!$I$6 -> 0 | K26: =[11]검사현황!$J$6 -> 0 | L26: =[11]검사현황!$K$6 -> 0 | M26: =[11]검사현황!$L$6 -> 0 | N26: =[11]검사현황!$M$6 -> 0 | O26: =[11]검사현황!$N$6 -> 0
A27: 신형 NUT | B27: 입고수 | C27: =[12]검사현황!$B$3 -> 0 | D27: =[12]검사현황!$C$3 -> 0 | E27: =[12]검사현황!$D$3 -> 0 | F27: =[12]검사현황!$E$3 -> 0 | G27: =[12]검사현황!$F$3 -> 0 | H27: =[12]검사현황!$G$3 -> 0 | I27: =[12]검사현황!$H$3 -> 0 | J27: =[12]검사현황!$I$3 -> 0 | K27: =[12]검사현황!$J$3 -> 500 | L27: =[12]검사현황!$K$3 -> 0 | M27: =[12]검사현황!$L$3 -> 2000 | N27: =[12]검사현황!$M$3 -> 0 | O27: =SUM(C27:N27) -> 2500
B28: 불량 % | C28: =[12]검사현황!$B$6 -> 0 | D28: =[12]검사현황!$C$6 -> 0 | E28: =[12]검사현황!$D$6 -> 0 | F28: =[12]검사현황!$E$6 -> 0 | G28: =[12]검사현황!$F$6 -> 0 | H28: =[12]검사현황!$G$6 -> 0 | I28: =[12]검사현황!$H$6 -> 0 | J28: =[12]검사현황!$I$6 -> 0 | K28: =[12]검사현황!$J$6 -> 12 | L28: =[12]검사현황!$K$6 -> 0 | M28: =[12]검사현황!$L$6 -> 0 | N28: =[12]검사현황!$M$6 -> 0
A29: 목표 | C29: 1 | D29: 1 | E29: 1 | F29: 1 | G29: 1 | H29: 1 | I29: 1 | J29: 1 | K29: 1 | L29: 1 | M29: 1 | N29: 1
A47: 업체 별 Reject Rate [%]
A48: 업체명 | C48: 1 | D48: 2 | E48: 3 | F48: 4 | G48: 5 | H48: 6 | I48: 7 | J48: 8 | K48: 9 | L48: 10 | M48: 11 | N48: 12 | O48: 합계
A49: =A3 -> CNB | B49: Lot 수[건] | C49: =[1]검사현황!$B$25 -> 2 | D49: =[1]검사현황!$C$25 -> 0 | E49: =[1]검사현황!$D$25 -> 6 | F49: =[1]검사현황!$E$25 -> 2 | G49: =[1]검사현황!$F$25 -> 2 | H49: =[1]검사현황!$G$25 -> 0 | I49: =[1]검사현황!$H$25 -> 2 | J49: =[1]검사현황!$I$25 -> 1 | K49: =[1]검사현황!$J$25 -> 6 | L49: =[1]검사현황!$K$25 -> 2 | M49: =[1]검사현황!$L$25 -> 0 | N49: =[1]검사현황!$M$25 -> 3 | O49: =SUM(C49:N49) -> 26
B50: 불합격[%] | C50: =[1]검사현황!$B$28 -> 0 | D50: =[1]검사현황!$C$28 -> 0 | E50: =[1]검사현황!$D$28 -> 0 | F50: =[1]검사현황!$E$28 -> 0 | G50: =[1]검사현황!$F$28 -> 0 | H50: =[1]검사현황!$G$28 -> 0 | I50: =[1]검사현황!$H$28 -> 0 | J50: =[1]검사현황!$I$28 -> 0 | K50: =[1]검사현황!$J$28 -> 0 | L50: =[1]검사현황!$K$28 -> 0 | M50: =[1]검사현황!$L$28 -> 0 | N50: =[1]검사현황!$M$28 -> 33.333333 | O50: =[1]검사현황!$N$28 -> 3.8461538 | Q50: Lot 수 | R50: =O49+O51+O53+O55+O57+O59+O61+O63+O67+O69+O71+O73 -> 208
A51: =A5 -> 미래 ENG | B51: Lot 수[건] | C51: =[2]검사현황!$B$25 -> 0 | D51: =[2]검사현황!$C$25 -> 5 | E51: =[2]검사현황!$D$25 -> 5 | F51: =[2]검사현황!$E$25 -> 19 | G51: =[2]검사현황!$F$25 -> 0 | H51: =[2]검사현황!$G$25 -> 4 | I51: =[2]검사현황!$H$25 -> 0 | J51: =[2]검사현황!$I$25 -> 3 | K51: =[2]검사현황!$J$25 -> 14 | L51: =[2]검사현황!$K$25 -> 0 | M51: =[2]검사현황!$L$25 -> 0 | N51: =[2]검사현황!$M$25 -> 2 | O51: =SUM(C51:N51) -> 52 | Q51: 불합격 수 | R51: 1
B52: 불합격[%] | C52: =[2]검사현황!$B$28 -> 0 | D52: =[2]검사현황!$C$28 -> 20 | E52: =[2]검사현황!$D$28 -> 0 | F52: =[2]검사현황!$E$28 -> 5.2631579 | G52: =[2]검사현황!$F$28 -> 0 | H52: =[2]검사현황!$G$28 -> 0 | I52: =[2]검사현황!$H$28 -> 0 | J52: =[2]검사현황!$I$28 -> 0 | K52: =[2]검사현황!$J$28 -> 0 | L52: =[2]검사현황!$K$28 -> 0 | M52: =[2]검사현황!$L$28 -> 0 | N52: =[2]검사현황!$M$28 -> 0 | O52: =[2]검사현황!$N$28 -> 3.8461538 | Q52: 불합격 % | R52: =R51*100/R50 -> 0.48076923
A53: =A7 -> 메탈 팩토리 | B53: Lot 수[건] | C53: =[3]검사현황!$B$25 -> 11 | D53: =[3]검사현황!$C$25 -> 5 | E53: =[3]검사현황!$D$25 -> 4 | F53: =[3]검사현황!$E$25 -> 2 | G53: =[3]검사현황!$F$25 -> 6 | H53: =[3]검사현황!$G$25 -> 2 | I53: =[3]검사현황!$H$25 -> 6 | J53: =[3]검사현황!$I$25 -> 7 | K53: =[3]검사현황!$J$25 -> 4 | L53: =[3]검사현황!$K$25 -> 10 | M53: =[3]검사현황!$L$25 -> 2 | N53: =[3]검사현황!$M$25 -> 5 | O53: =SUM(C53:N53) -> 64
B54: 불합격[%] | C54: =[3]검사현황!$B$28 -> 0 | D54: =[3]검사현황!$C$28 -> 20 | E54: =[3]검사현황!$D$28 -> 0 | F54: =[3]검사현황!$E$28 -> 50 | G54: =[3]검사현황!$F$28 -> 0 | H54: =[3]검사현황!$G$28 -> 0 | I54: =[3]검사현황!$H$28 -> 16.666667 | J54: =[3]검사현황!$I$28 -> 0 | K54: =[3]검사현황!$J$28 -> 0 | L54: =[3]검사현황!$K$28 -> 0 | M54: =[3]검사현황!$L$28 -> 0 | N54: =[3]검사현황!$M$28 -> 20 | O54: =[3]검사현황!$N$28 -> 6.25
A55: =A9 -> 전진로링 | B55: Lot 수[건] | C55: =[4]검사현황!$B$25 -> 2 | D55: =[4]검사현황!$C$25 -> 0 | E55: =[4]검사현황!$D$25 -> 2 | F55: =[4]검사현황!$E$25 -> 0 | G55: =[4]검사현황!$F$25 -> 1 | H55: =[4]검사현황!$G$25 -> 0 | I55: =[4]검사현황!$H$25 -> 1 | J55: =[4]검사현황!$I$25 -> 2 | K55: =[4]검사현황!$J$25 -> 1 | L55: =[4]검사현황!$K$25 -> 2 | M55: =[4]검사현황!$L$25 -> 0 | N55: =[4]검사현황!$M$25 -> 4 | O55: =SUM(C55:N55) -> 15
B56: 불합격[%] | C56: =[4]검사현황!$B$28 -> 0 | D56: =[4]검사현황!$C$28 -> 0 | E56: =[4]검사현황!$D$28 -> 0 | F56: =[4]검사현황!$E$28 -> 0 | G56: =[4]검사현황!$F$28 -> 0 | H56: =[4]검사현황!$G$28 -> 0 | I56: =[4]검사현황!$H$28 -> 0 | J56: =[4]검사현황!$I$28 -> 0 | K56: =[4]검사현황!$J$28 -> 0 | L56: =[4]검사현황!$K$28 -> 0 | M56: =[4]검사현황!$L$28 -> 0 | N56: =[4]검사현황!$M$28 -> 0 | O56: =[4]검사현황!$N$28 -> 0
A57: =A11 -> 시대전자 | B57: Lot 수[건] | C57: =[5]검사현황!$B$25 -> 0 | D57: =[5]검사현황!$C$25 -> 0 | E57: =[5]검사현황!$D$25 -> 2 | F57: =[5]검사현황!$E$25 -> 3 | G57: =[5]검사현황!$F$25 -> 0 | H57: =[5]검사현황!$G$25 -> 0 | I57: =[5]검사현황!$H$25 -> 0 | J57: =[5]검사현황!$I$25 -> 0 | K57: =[5]검사현황!$J$25 -> 2 | L57: =[5]검사현황!$K$25 -> 1 | M57: =[5]검사현황!$L$25 -> 0 | N57: =[5]검사현황!$M$25 -> 0 | O57: =SUM(C57:N57) -> 8
...

Sheet 업체별 현황
B2: #불량% | O2: 월 별 불량 률[%]
B3: 업체명 | C3: 납품수량 | D3: 검사 수 | E3: 불량 수 | F3: 불량 % | P3: 1 | Q3: 2 | R3: 3 | S3: 4 | T3: 5 | U3: 6 | V3: 7 | W3: 8 | X3: 9 | Y3: 10 | Z3: 11 | AA3: 12 | AB3: 합계
B4: 일흥테크 | C4: =수입검사!O13 -> 3500 | F4: =수입검사!O14 -> 14.285714 | O4: 메탈팩토리 | P4: =수입검사!C10 -> 0 | Q4: =수입검사!D10 -> 0 | R4: =수입검사!E10 -> 0 | S4: =수입검사!F10 -> 0 | T4: =수입검사!G10 -> 0 | U4: =수입검사!H10 -> 0 | V4: =수입검사!I10 -> 0 | W4: =수입검사!J10 -> 0 | ... AA4: =수입검사!N10 -> 0
B5: 메탈 팩토리 | C5: =수입검사!O7 -> 84408 | F5: =수입검사!O8 -> 7.5466595 | O5: 대신 플라텍 | P5: =SUM(수입검사!C6) -> 0 | Q5: =SUM(수입검사!D6) -> 0.65789474 | R5: =SUM(수입검사!E6) -> 0 | S5: =SUM(수입검사!F6) -> 4.6728972 | T5: =SUM(수입검사!G6) -> 0 | U5: =SUM(수입검사!H6) -> 0 | V5: =SUM(수입검사!I6) -> 0 | W5: =SUM(수입검사!J6) -> 0 | ... AA5: =SUM(수입검사!N6) -> 0
B6: 미래 ENG | C6: =수입검사!O5 -> 135720 | F6: =수입검사!O6 -> 1.7931034 | O6: 전진로링 | P6: =SUM(수입검사!C8) -> 0 | Q6: =SUM(수입검사!D8) -> 20 | R6: =SUM(수입검사!E8) -> 69.230769 | S6: =SUM(수입검사!F8) -> 5 | T6: =SUM(수입검사!G8) -> 0 | U6: =SUM(수입검사!H8) -> 0 | V6: =SUM(수입검사!I8) -> 5.6872038 | W6: =SUM(수입검사!J8) -> 0 | ... AA6: =SUM(수입검사!N8) -> 12.5
B7: 시너지테크 | C7: =수입검사!O15 -> 10337 | F7: =수입검사!O16 -> 1.0356732 | O7: 유니프로 | P7: =SUM(수입검사!C4) -> 0 | Q7: =SUM(수입검사!D4) -> 0 | R7: =SUM(수입검사!E4) -> 0 | S7: =SUM(수입검사!F4) -> 0 | T7: =SUM(수입검사!G4) -> 0 | U7: =SUM(수입검사!H4) -> 0 | V7: =SUM(수입검사!I4) -> 0 | W7: =SUM(수입검사!J4) -> 0 | ... AA7: =SUM(수입검사!N4) -> 3.3333333
B8: 유니프로 | C8: =수입검사!O21 -> 302000 | F8: =수입검사!O22 -> 0 | O8: 갑텍 | P8: =수입검사!C12 -> 0 | Q8: =수입검사!D12 -> 0 | R8: =수입검사!E12 -> 0 | S8: =수입검사!F12 -> 0 | T8: =수입검사!G12 -> 0 | U8: =수입검사!H12 -> 0 | V8: =수입검사!I12 -> 0 | W8: =수입검사!J12 -> 0 | ... AA8: =수입검사!N12 -> 0
B9: JMT | C9: =수입검사!O23 -> 24066 | F9: =수입검사!O24 -> 0 | O9: 아름정밀 | P9: =수입검사!C16 -> 0 | Q9: =수입검사!D16 -> 0 | R9: =수입검사!E16 -> 0 | S9: =수입검사!F16 -> 1.6990291 | T9: =수입검사!G16 -> 0 | U9: =수입검사!H16 -> 1.0152284 | V9: =수입검사!I16 -> 0 | W9: =수입검사!J16 -> 0 | ... AA9: =수입검사!N16 -> 0
B10: 천호금속 | C10: =수입검사!O17 -> 2500 | F10: =수입검사!O18 -> 0
B11: CNB | C11: =수입검사!O3 -> 27000 | F11: =수입검사!O4 -> 0.21551724
B12: 전진로링 | C12: =수입검사!O9 -> 11417 | F12: =수입검사!O10 -> 0
B13: 시대전자 | C13: =수입검사!O11 -> 10760 | F13: =수입검사!O12 -> 0
B14: 태광시스템 | C14: =수입검사!O19 -> 0 | F14: =수입검사!O20 -> 0
B15: 신형 NUT | C15: =수입검사!O27 -> 2500 | F15: =수입검사!O28 -> 0
B16: 합계 | C16: =SUM(C12:C14) -> 22177 | D16: =SUM(D12:D14) -> 0 | E16: =SUM(E12:E14) -> 0 | F16: =IFERROR(E16*100/D16,"0") -> 0
B20: #불합격%
B21: 업체명 | C21: Lot 수 | D21: 검사 수 | E21: 불합격 수 | F21: RE Rate[%]
B22: 일흥테크 | C22: =수입검사!O59 -> 7 | F22: =수입검사!O60 -> 14.285714
B23: 메탈 팩토리 | C23: =수입검사!O53 -> 64 | F23: =수입검사!O54 -> 6.25
B24: 미래 ENG | C24: =수입검사!O51 -> 52 | F24: =수입검사!O52 -> 3.8461538
B25: CNB | C25: =수입검사!O49 -> 26 | F25: =수입검사!O50 -> 3.8461538
B26: 전진로링 | C26: =수입검사!O55 -> 15 | F26: =수입검사!O56 -> 0
B27: 시대전자 | C27: =수입검사!O57 -> 8 | F27: =수입검사!O58 -> 0
B28: 시너지테크 | C28: =수입검사!O61 -> 9 | F28: =수입검사!O62 -> 0
B29: 천호금속 | C29: =수입검사!O63 -> 5 | F29: =수입검사!O64 -> 0 | O29: 월 별 Reject Rate[%]
B30: 태광시스템 | C30: =수입검사!O65 -> 0 | F30: =수입검사!O66 -> 0 | P30: 1 | Q30: 2 | R30: 3 | S30: 4 | T30: 5 | U30: 6 | V30: 7 | W30: 8 | X30: 9 | Y30: 10 | Z30: 11 | AA30: 12
B31: 유니프로 | C31: =수입검사!O67 -> 5 | F31: =수입검사!O68 -> 0 | O31: 메탈팩토리 | P31: =수입검사!C56 -> 0 | Q31: =수입검사!D56 -> 0 | R31: =수입검사!E56 -> 0 | S31: =수입검사!F56 -> 0 | T31: =수입검사!G56 -> 0 | U31: =수입검사!H56 -> 0 | V31: =수입검사!I56 -> 0 | W31: =수입검사!J56 -> 0 | ... AA31: =수입검사!N56 -> 0
B32: JMT | C32: =수입검사!O69 -> 8 | F32: =수입검사!O70 -> 0 | O32: 대신 프라텍 | P32: =SUM(수입검사!C52) -> 0 | Q32: =SUM(수입검사!D52) -> 20 | R32: =SUM(수입검사!E52) -> 0 | S32: =SUM(수입검사!F52) -> 5.2631579 | T32: =SUM(수입검사!G52) -> 0 | U32: =SUM(수입검사!H52) -> 0 | V32: =SUM(수입검사!I52) -> 0 | W32: =SUM(수입검사!J52) -> 0 | ... AA32: =SUM(수입검사!N52) -> 0
B33: 신형 NUT | C33: =수입검사!O73 -> 3 | F33: =수입검사!O70 -> 0 | O33: 전진로링 | P33: =SUM(수입검사!C54) -> 0 | Q33: =SUM(수입검사!D54) -> 20 | R33: =SUM(수입검사!E54) -> 0 | S33: =SUM(수입검사!F54) -> 50 | T33: =SUM(수입검사!G54) -> 0 | U33: =SUM(수입검사!H54) -> 0 | V33: =SUM(수입검사!I54) -> 16.666667 | W33: =SUM(수입검사!J54) -> 0 | ... AA33: =SUM(수입검사!N54) -> 20
B34: 합계 | C34: =SUM(C23:C31) -> 184 | D34: =SUM(D23:D31) -> 0 | E34: =SUM(E23:E31) -> 0 | F34: =IFERROR(E34*10/D34,"0") -> 0 | O34: 유니프로 | P34: =SUM(수입검사!C50) -> 0 | Q34: =SUM(수입검사!D50) -> 0 | R34: =SUM(수입검사!E50) -> 0 | S34: =SUM(수입검사!F50) -> 0 | T34: =SUM(수입검사!G50) -> 0 | U34: =SUM(수입검사!H50) -> 0 | V34: =SUM(수입검사!I50) -> 0 | W34: =SUM(수입검사!J50) -> 0 | ... AA34: =SUM(수입검사!N50) -> 33.333333
O35: 갑텍 | P35: =수입검사!C58 -> 0 | Q35: =수입검사!D58 -> 0 | R35: =수입검사!E58 -> 0 | S35: =수입검사!F58 -> 0 | T35: =수입검사!G58 -> 0 | U35: =수입검사!H58 -> 0 | V35: =수입검사!I58 -> 0 | W35: =수입검사!J58 -> 0 | ... AA35: =수입검사!N58 -> 0
O36: 아름정밀 | P36: =수입검사!C62 -> 0 | Q36: =수입검사!D62 -> 0 | R36: =수입검사!E62 -> 0 | S36: =수입검사!F62 -> 0 | T36: =수입검사!G62 -> 0 | U36: =수입검사!H62 -> 0 | V36: =수입검사!I62 -> 0 | W36: =수입검사!J62 -> 0 | ... AA36: =수입검사!N62 -> 0
