Workbook
Name EZ_Control: 기준정보!$D$158
Name Isolation_Module: 기준정보!$D$169:$D$170
Name Linear_servo_FC: 기준정보!$D$2:$D$81
Name Linear_servo_PC: 기준정보!$D$83:$D$142
Name Mini_SW: 기준정보!$D$144:$D$151
Name Model: [1]기준정보!$B$2:$B$11
Name Model: 기준정보!$B$2:$B$16
Name Nano_SW: 기준정보!$D$153:$D$155
Name Raspberry_Pi: 기준정보!$D$161
Name Round_Servo: 기준정보!$D$173:$D$175
Name Servo_Testshield: 기준정보!$D$160
Name UART_Interface: 기준정보!$D$167
Name USB_Interface: 기준정보!$D$164:$D$165
Name 검사결과: [2]기준정보!$H$2:$H$3
Name 검사방법: [1]기준정보!$E$2:$E$3
Name 검사방법: 기준정보!$E$2:$E$4
Name 규격: [1]기준정보!$D$2:$D$157
Name 규격: 기준정보!$D$2:$D$168
Name 도번: #REF!
Name 도번: #REF!

Sheet 월 품질 현황
A1: 2025년도 공정 검사 현황
A2: 년 | B2: 항목／월 | C2: 1 | D2: 2 | E2: 3 | F2: 4 | G2: 5 | H2: 6 | I2: 7 | J2: 8 | K2: 9 | L2: 10 | M2: 11 | N2: 12 | O2: 합계 | P2: 평균 | R2: 2025년도 | U2: 2024년도 | AG2: #제조 일자 표기
A3: 2025년 | B3: 검사 수 | C3: ='1월'!C3 -> 548 | D3: ='2월'!C3 -> 415 | E3: ='3월'!C3 -> 712 | F3: ='4월'!C3 -> 836 | G3: ='5월'!C3 -> 821 | H3: ='6월'!C3 -> 1013 | I3: ='7월'!C3 -> 968 | J3: ='8월'!C3 -> 868 | K3: ='9월'!C3 -> 922 | L3: ='10월'!C3 -> 594 | M3: ='11월'!C3 -> 430 | N3: ='12월'!C3 -> 413 | O3: =SUM(C3:N3) -> 8540 | P3: =AVERAGEIF(C3:N3,">0") -> 711.66667 | R3: 항목 기간 | S3: 품질 목표 | T3: 불량% | U3: 항목 기간 | V3: 품질 목표 | W3: 불량% | AG3: 년 | AH3: 표기 | AJ3: 월(알파벳순)
B4: 불량 수 | C4: ='1월'!F3 -> 15 | D4: ='2월'!F3 -> 18 | E4: ='3월'!F3 -> 17 | F4: ='4월'!F3 -> 8 | G4: ='5월'!F3 -> 12 | H4: ='6월'!F3 -> 7 | I4: ='7월'!F3 -> 7 | J4: ='8월'!F3 -> 6 | K4: ='9월'!F3 -> 11 | L4: ='10월'!F3 -> 7 | M4: ='11월'!F3 -> 5 | N4: ='12월'!F3 -> 2 | O4: =SUM(C4:N4) -> 115 | P4: =AVERAGEIF(C4:N4,">0") -> 9.5833333 | R4: 상반기 | S4: 0.03 | T4: =IFERROR((SUM(C4:H4)/SUM(C3:H3)*100),"0") -> 1.7721519 | U4: 상반기 | V4: 0.05 | W4: 1.84 | AG4: 2017 | AH4: 0 | AJ4: A | AK4: B | AL4: C | AM4: D | AN4: E | AO4: F | AP4: G | AQ4: H | AR4: I | AS4: J | AT4: K | AU4: L
B5: 2025년 불량% | C5: =IFERROR(C4*100/C3,"0") -> 2.7372263 | D5: =IFERROR(D4*100/D3,"0") -> 4.3373494 | E5: =IFERROR(E4*100/E3,"0") -> 2.3876404 | F5: =IFERROR(F4*100/F3,"0") -> 0.9569378 | G5: =IFERROR(G4*100/G3,"0") -> 1.4616322 | H5: =IFERROR(H4*100/H3,"0") -> 0.69101678 | I5: =IFERROR(I4*100/I3,"0") -> 0.7231405 | J5: =IFERROR(J4*100/J3,"0") -> 0.69124424 | ... O5: =IFERROR(O4*100/O3,"0") -> 1.3466042 | P5: =AVERAGEIF(C5:N5,">0") -> 1.5003958 | R5: 하반기 | S5: 0.03 | T5: =IFERROR((SUM(I4:N4)/SUM(I3:N3)*100),"0") -> 0.90584029 | U5: 하반기 | V5: 0.05 | W5: 2.35 | AF5: 2018 | AG5: 1 | AI5: 1 | AJ5: 2 | AK5: 3 | AL5: 4 | AM5: 5 | AN5: 6 | AO5: 7 | AP5: 8 | AQ5: 9 | AR5: 10 | AS5: 11 | AT5: 12
B6: 유효 생산 수 | C6: =C3-C4 -> 533 | D6: =D3-D4 -> 397 | E6: =E3-E4 -> 695 | F6: =F3-F4 -> 828 | G6: =G3-G4 -> 809 | H6: =H3-H4 -> 1006 | I6: =I3-I4 -> 961 | J6: =J3-J4 -> 862 | ... N6: =N3-N4 -> 411 | O6: =SUM(C6:N6) -> 8425 | P6: =AVERAGEIF(C6:N6,">0") -> 702.08333 | R6: 년간 | S6: =O5 -> 1.3466042 | U6: 년간 | V6: 2.14 | AG6: 2019 | AH6: 2
A7: 2024년 | B7: 검사 수 | C7: 566 | D7: 288 | E7: 639 | F7: 602 | G7: 1005 | H7: 1081 | I7: 723 | J7: 1543 | K7: 663 | L7: 616 | M7: 1168 | N7: 1104 | O7: 9998 | P7: =AVERAGEIF(C7:N7,">0") -> 833.16667 | AH7: 2020 | AI7: 3
B8: 2024년 불량% | C8: 3.36 | D8: 2.43 | E8: 1.72 | F8: 2.33 | G8: 1.39 | H8: 1.11 | I8: 3.04 | J8: 1.48 | K8: 4.52 | L8: 4.38 | M8: 1.88 | N8: 1.18 | O8: 2.14 | P8: =AVERAGEIF(C8:N8,">0") -> 2.4016667 | AH8: 2021 | AI8: 4
B9: 유효 생산 수 | C9: 547 | D9: 281 | E9: 628 | F9: 588 | G9: 991 | H9: 1069 | I9: 701 | J9: 1520 | K9: 633 | L9: 589 | M9: 1146 | N9: 1091 | O9: 9784 | P9: =AVERAGEIF(C9:N9,">0") -> 815.33333 | AH9: 2022 | AI9: 5
AG10: 2023 | AH10: 6
AG11: 2024 | AH11: 7
AG12: 2025 | AH12: 8
AG13: 2026 | AH13: 9
AG14: 2027 | AH14: 10
AG15: 2028 | AH15: 11
B17: 월 평균 생산 수 | C17: =O17 -> 728.54545 | D17: =O17 -> 728.54545 | E17: =O17 -> 728.54545 | F17: =O17 -> 728.54545 | G17: =O17 -> 728.54545 | H17: =O17 -> 728.54545 | I17: =O17 -> 728.54545 | J17: =O17 -> 728.54545 | K17: =O17 -> 728.54545 | L17: =O17 -> 728.54545 | M17: =O17 -> 728.54545 | N17: =O17 -> 728.54545 | O17: =AVERAGE(C6:M6) -> 728.54545
B18: 목표% | C18: 3 | D18: 3 | E18: 3 | F18: 3 | G18: 3 | H18: 3 | I18: 3 | J18: 3 | K18: 3 | L18: 3 | M18: 3 | N18: 3
B19: 연간 불량% | C19: =$O$5 -> 1.3466042 | D19: =$O$5 -> 1.3466042 | E19: =$O$5 -> 1.3466042 | F19: =$O$5 -> 1.3466042 | G19: =$O$5 -> 1.3466042 | H19: =$O$5 -> 1.3466042 | I19: =$O$5 -> 1.3466042 | J19: =$O$5 -> 1.3466042 | ... N19: =$O$5 -> 1.3466042
A38: #1. 100/64 N New firmware 적용 및 검사 완료 Sticker blue to yellow 첫 적용
A39: #2. 이구스 대체 Metal Rod 첫 적용 | V39: #. Inspection sticker 구분
A40: #3. Hysterisis 및 Recalibration 오작동 관련 Firmware 수정 : 대상 F , PT Version 1차 수정시 Over load protection program 관련 오류로 2차 Program 수정 후 기존 검사 품 재작업. | V40: Color | W40: 변경 내용
A41: #4. 특정(지정) Buyer 를 제외 하고 20N 이상 제품 Rod SUS로 교체 적용 (AUG. 2018) | P41: # Firmware version 구분 | W41: TVS Diode 적용
A42: #5. D12-12PT-3 Lead screw 변경 (1월 31일) | P42: No. | Q42: Model | R42: Version | S42: Sticker | T42: update | W42: Program Reset 시 Over load protect function 해제 문제
A43: #6. L12-20PT-4 Bounding 문제로 Firmware 수정 적용 | P43: 1 | Q43: D7-6PT-3 | R43: 3 | T43: 4 | W43: Over load protect 설정에 따라 Reset 시 Recalibration 및 Hysterisis 적용
A44: #7. L12-80F-6 Overshoot에 의한 bounding 개선으로 firmware 수정 (Version "0" to "1"). | P44: 2 | Q44: D7-12PT-3 | R44: 3 | T44: 4
A45: #8. L12-100F-3 Force limit 미작동 수정 firmware (3D25_v4) | P45: 3 | Q45: L7-40PT-3 | R45: 3
A46: #9. New Over load Protection 적용 변경 6월 | P46: 4 | Q46: L7-20PT-3 | R46: 4 | T46: 5
A47: #10. Firmware 변경 사항(2019년 2월 22일 단순 메일 공지 첨부 서류 또는 ECO 없음) | P47: 5 | Q47: L7-100PT-3 | R47: 2
P48: 6 | Q48: D12-6PT-3 | R48: 3
P49: 7 | Q49: D12-12PT-3 | R49: 3 | T49: 4
P50: 8 | Q50: L12-20F-3 | R50: 3 | T50: 4
P51: 9 | Q51: L12-40F-3 | R51: 3 | T51: 4
P52: 10 | Q52: L12-64F-3 | R52: 2
P53: 11 | Q53: L12-100F-3 | R53: 2
P54: 12 | Q54: L12-20PT-3 | R54: 5
P55: 13 | Q55: L12-40PT-3 | R55: 3
P56: 14 | Q56: L12-64PT-3 | R56: 2 | T56: 3
P57: 15 | Q57: L12-100PT-3 | R57: 2
P58: 16 | Q58: L12-17PT-6 | R58: 0 | T58: 1
P59: 17 | Q59: L12-20PT-6 | R59: 0 | T59: 1
...

Sheet SW Version

Sheet Refirm 내용

Sheet 연구소 PC Ver 설계 변경 내용
B2: PC Ver 설계 변경내용
B5: Ver | C5: 적용 일자 | D5: 변경파일 | E5: 변경전 | F5: 변경후 | G5: 업데이트 목적
B6: 1.4G | C6: 2019.3.15 | D6: PID값 변경 | E6: - | F6: PID 제어값 개선 | G6: 모션종단의 간헐적 지터현상 개선
D7: Overload Shutdown 레벨 조정 | E7: - | F7: Overload Shutdonw 기능 덜 민감하게 조정
D8: Low voltage error 범위 조정(12V) | E8: 9V ~ 13V 범위 밖 | F8: 13V 이상에서만 에러 발생(하한값 제거)
D9: Low voltage error 범위 조정(7.4V) | E9: 6V ~ 8.9V 범위 밖 | F9: 8.9V 이상에서만 에러 발생(하한값 제거)
D10: Overload Shutdown 리셋 | E10: 전원 재 인가시에만 서보 재 시작 | F10: Overload shutdonw 이후, Restaret 명령을 이용해 리셋
B11: 1.5G | C11: 2019.07.22 | D11: Overload Protection | E11: 모델 별 개별 SPEC | F11: 전 제품 30초 연속 가동시 Motor Cut off(위치 변동 x)
D12: Force Limit 기능 삭제 | F12: Force Limit 기능 삭제
D13: Max Force 명칭 변경 | E13: Max Force | F13: Motor Operating Rate로 변경
D14: Motor Operatuing rate 범위 | E14: 0~1023 | F14: 400~1023 | G14: 400이하시 모터 미동작
D15: Speed 파라메터 제거 | E15: 부자연 스러운 속도제어 | F15: Motor Operating Rate변경을 통한 간이속도 제어 | G15: 부자연 스러운 속도제어
D16: 장애물 감지 | F16: 장애물감지시 Force Limit를 400으로 set
D17: Compliance Margin | F17: Start Compliance와 End Compliance margin으로 변경
B18: 1.6G | C18: 2020.05.18 | D18: Calibration.c | E18: Calibration start pwm 400 | F18: Calibration start pwm 800
B20: 1.7G | C20: 2020.10.14 | D20: SV.c(12V lineup only) | E20: #define DEFAULT_DOWN_LIMIT_VOLTAGE 90 | F20: #define DEFAULT_DOWN_LIMIT_VOLTAGE 70
D21: SV.c | E21: #define DEFAULT_CW_COMPLIANCE_MARGIN xx #define DEFAULT_CCW_COMPLIANCE_MARGIN xx | F21: #define DEFAULT_CW_COMPLIANCE_MARGIN 7 #define DEFAULT_CCW_COMPLIANCE_MARGIN 7 | G21: Margin 값 통일
D22: Error.c | E22: Low Voltage Error 미확인 | F22: Low Voltage Error 확인
D23: MotorDirve.c | E23: Moving Update 안함 | F23: Moving Update 추가 | G23: Moving 함수 미적용(부정확 동작)
D24: PulsePositioncontrol.c | F24: GoalPosition값에 끝단 자르는값 적용 | G24: PWM/TTL '0'위치 미일치
G25: 모터 정지시 Break
D26: Protocol_RxProcess.c | F26: 0x84에 ㅡMotor Stop 기능 추가 정지 시 현지위치값을 GoalPosition 값으로 저장
B27: 1.8G | C27: 2021.02.18 | D27: TTL/PWM 동기화 | E27: TT/PWM 신호 동기화 | F27: TTL/PWM 신호 동기화
D28: center difference | E28: 수정가능 | F28: 수정불가
B29: 1.9G | C29: 2021.02.22 | D29: Force Off | E29: force Off후 반대 방향 이동 시 튀는현상 (수정 후 발생) Force Off후에도 Overload 발생 (수정 후 발생) | F29: force Off후 반대방향 이동에도 튀지 않음 Force Off후에도 Overload 발생하지 않음
B30: V20 | C30: 2021.10.04 | D30: Baudrate 38400 | E30: 미지원 | F30: 지원
D31: 메모리 안정화 | E31: 부팅시 메모리 쓰기 진행 | F31: 부팅시 메모리 쓰기 안함
D32: 전원 부팅시 Force Enable | E32: 전원 부팅시 Force Disable | F32: 전원 부팅시 Force Enable
D33: Return Delay | E33: 0~255 | F33: Baudrate에 따른 고정값으로 변경
D34: PWN 통신 | E34: 작은 노이즈에도 PWM 반응 | F34: 노이즈에 의한 오동작 방지
D35: Position Calibration | E35: 미지원 | F35: Min/Max Position Calibration 기능 추가
D36: Acceleration Rate/ Deceleration Rate | E36: 값에 대한 변화가 적음 | F36: 부드러운 제어 기능
D37: Erroe state | E37: Instruction Error Overload Error checksum Error Range Error Stroke Limit Error Input Voltage Error | F37: Overload Error Input Voltage Error
D38: Stroke Pulse with | E38: 변경가능 | F38: 변경 불가능
D39: Center Difference | E39: 변경가능 | F39: 파라메터 삭제 ->고정값
D40: Punch/Punch Initial Value | E40: 지원 | F40: Acc 기능에 포함
D41: Compliacne Margin | E41: 고정값 | F41: FC에서 제공하던 Start /End Compliance Margin 추가
D42: 제품 표기 | E42: V1.8 | F42: V20
B43: V21 | C43: 2022.01.14 | D43: Min Position Calibratiion | E43: 미지원 | F43: 지원
D44: Max Position Calibratiion | E44: 미지원 | F44: 지원

Sheet Model별 품질현황
I1: 검사수 | J1: 불량수 | K1: 양품수 | L1: 불량%
A2: No. | B2: Model | C2: 검사 수[EA] | D2: 불량 수[EA] | E2: 불량[%] | H2: 합계 | I2: =SUM(C3:C176) -> 8540 | J2: =SUM(D3:D176) -> 115 | K2: =I2-J2 -> 8425 | L2: =J2/I2 -> 0.013466042
A3: 125 | B3: 12Lf-55PT-40 | C3: =SUM('생산 현황'!C127) -> 8 | D3: =SUM('생산 현황'!D127) -> 5 | E3: =SUM('생산 현황'!E127) -> 62.5
A4: 137 | B4: 12Lf-17PT-53 | C4: =SUM('생산 현황'!C139) -> 14 | D4: =SUM('생산 현황'!D139) -> 4 | E4: =SUM('생산 현황'!E139) -> 28.571429
A5: 121 | B5: 12Lf-17PT-40 | C5: =SUM('생산 현황'!C123) -> 18 | D5: =SUM('생산 현황'!D123) -> 3 | E5: =SUM('생산 현황'!E123) -> 16.666667
A6: 150 | B6: 12Lf-55F-53 | C6: =SUM('생산 현황'!C152) -> 6 | D6: =SUM('생산 현황'!D152) -> 1 | E6: =SUM('생산 현황'!E152) -> 16.666667
A7: 156 | B7: 12Lf-17F-90 | C7: =SUM('생산 현황'!C158) -> 17 | D7: =SUM('생산 현황'!D158) -> 2 | E7: =SUM('생산 현황'!E158) -> 11.764706
A8: 148 | B8: 12Lf-27F-53 | C8: =SUM('생산 현황'!C150) -> 17 | D8: =SUM('생산 현황'!D150) -> 2 | E8: =SUM('생산 현황'!E150) -> 11.764706
A9: 126 | B9: 12Lf-78PT-40 | C9: =SUM('생산 현황'!C128) -> 17 | D9: =SUM('생산 현황'!D128) -> 2 | E9: =SUM('생산 현황'!E128) -> 11.764706
A10: 133 | B10: 12Lf-55F-40 | C10: =SUM('생산 현황'!C135) -> 19 | D10: =SUM('생산 현황'!D135) -> 2 | E10: =SUM('생산 현황'!E135) -> 10.526316
A11: 163 | B11: 17Lf-50F-37 | C11: =SUM('생산 현황'!C165) -> 11 | D11: =SUM('생산 현황'!D165) -> 1 | E11: =SUM('생산 현황'!E165) -> 9.0909091
A12: 119 | B12: 12Lf-10PT-40 | C12: =SUM('생산 현황'!C121) -> 22 | D12: =SUM('생산 현황'!D121) -> 2 | E12: =SUM('생산 현황'!E121) -> 9.0909091
A13: 164 | B13: 17Lf-17F-50 | C13: =SUM('생산 현황'!C166) -> 22 | D13: =SUM('생산 현황'!D166) -> 2 | E13: =SUM('생산 현황'!E166) -> 9.0909091
A14: 152 | B14: 12Lf-10PT-90 | C14: =SUM('생산 현황'!C154) -> 16 | D14: =SUM('생산 현황'!D154) -> 1 | E14: =SUM('생산 현황'!E154) -> 6.25
A15: 169 | B15: 17Lf-50F-87 | C15: =SUM('생산 현황'!C171) -> 49 | D15: =SUM('생산 현황'!D171) -> 3 | E15: =SUM('생산 현황'!E171) -> 6.122449
A16: 131 | B16: 12Lf-27F-40 | C16: =SUM('생산 현황'!C133) -> 33 | D16: =SUM('생산 현황'!D133) -> 2 | E16: =SUM('생산 현황'!E133) -> 6.0606061
A17: 154 | B17: 12Lf-27PT-90 | C17: =SUM('생산 현황'!C156) -> 34 | D17: =SUM('생산 현황'!D156) -> 2 | E17: =SUM('생산 현황'!E156) -> 5.8823529
A18: 58 | B18: 17Lf-70F-27 | C18: =SUM('생산 현황'!C60) -> 37 | D18: =SUM('생산 현황'!D60) -> 2 | E18: =SUM('생산 현황'!E60) -> 5.4054054
A19: 129 | B19: 12Lf-17F-40 | C19: =SUM('생산 현황'!C131) -> 114 | D19: =SUM('생산 현황'!D131) -> 6 | E19: =SUM('생산 현황'!E131) -> 5.2631579
A20: 166 | B20: 17Lf-50F-50 | C20: =SUM('생산 현황'!C168) -> 42 | D20: =SUM('생산 현황'!D168) -> 2 | E20: =SUM('생산 현황'!E168) -> 4.7619048
A21: 127 | B21: 12Lf-10F-40 | C21: =SUM('생산 현황'!C129) -> 46 | D21: =SUM('생산 현황'!D129) -> 2 | E21: =SUM('생산 현황'!E129) -> 4.3478261
A22: 77 | B22: L12-80F-4 | C22: =SUM('생산 현황'!C79) -> 207 | D22: =SUM('생산 현황'!D79) -> 9 | E22: =SUM('생산 현황'!E79) -> 4.3478261
A23: 168 | B23: 17Lf-27F-87 | C23: =SUM('생산 현황'!C170) -> 25 | D23: =SUM('생산 현황'!D170) -> 1 | E23: =SUM('생산 현황'!E170) -> 4
A24: 80 | B24: L12-20F-6 | C24: =SUM('생산 현황'!C82) -> 54 | D24: =SUM('생산 현황'!D82) -> 2 | E24: =SUM('생산 현황'!E82) -> 3.7037037
A25: 68 | B25: 12D-12S-15 | C25: =SUM('생산 현황'!C70) -> 30 | D25: =SUM('생산 현황'!D70) -> 1 | E25: =SUM('생산 현황'!E70) -> 3.3333333
A26: 142 | B26: 12Lf-78PT-53 | C26: =SUM('생산 현황'!C144) -> 62 | D26: =SUM('생산 현황'!D144) -> 2 | E26: =SUM('생산 현황'!E144) -> 3.2258065
A27: 153 | B27: 12Lf-17PT-90 | C27: =SUM('생산 현황'!C155) -> 31 | D27: =SUM('생산 현황'!D155) -> 1 | E27: =SUM('생산 현황'!E155) -> 3.2258065
A28: 50 | B28: 12Lf-35PT-27 | C28: =SUM('생산 현황'!C52) -> 80 | D28: =SUM('생산 현황'!D52) -> 2 | E28: =SUM('생산 현황'!E52) -> 2.5
A29: 46 | B29: 12Lf-12PT-27 | C29: =SUM('생산 현황'!C48) -> 96 | D29: =SUM('생산 현황'!D48) -> 2 | E29: =SUM('생산 현황'!E48) -> 2.0833333
A30: 49 | B30: 12Lf-20PT-27 | C30: =SUM('생산 현황'!C51) -> 150 | D30: =SUM('생산 현황'!D51) -> 3 | E30: =SUM('생산 현황'!E51) -> 2
A31: 39 | B31: 12Lf-100F-27 | C31: =SUM('생산 현황'!C41) -> 386 | D31: =SUM('생산 현황'!D41) -> 6 | E31: =SUM('생산 현황'!E41) -> 1.5544041
A32: 55 | B32: 12Lf-12PT-27EL | C32: =SUM('생산 현황'!C57) -> 67 | D32: =SUM('생산 현황'!D57) -> 1 | E32: =SUM('생산 현황'!E57) -> 1.4925373
A33: 157 | B33: 12Lf-27F-90 | C33: =SUM('생산 현황'!C159) -> 70 | D33: =SUM('생산 현황'!D159) -> 1 | E33: =SUM('생산 현황'!E159) -> 1.4285714
A34: 23 | B34: L12-100F-3 | C34: =SUM('생산 현황'!C25) -> 213 | D34: =SUM('생산 현황'!D25) -> 3 | E34: =SUM('생산 현황'!E25) -> 1.4084507
A35: 53 | B35: 12Lf-100PT-27 | C35: =SUM('생산 현황'!C55) -> 78 | D35: =SUM('생산 현황'!D55) -> 1 | E35: =SUM('생산 현황'!E55) -> 1.2820513 | G35: Model | I35: Dead | J35: GC 200 | K35: LED | L35: Noise | M35: Straightness | N35: Speed | O35: Chattering | P35: Bounding | Q35: Over Current | R35: Hinge Nut | S35: Stroke | T35: Slip | U35: Jitter | V35: CH Dead | W35: Screw Missing | X35: MP | Y35: S/C | Z35: Gap | AA35: ETC | AB35: 합계
A36: 86 | B36: L12-80F-6 | C36: =SUM('생산 현황'!C88) -> 102 | D36: =SUM('생산 현황'!D88) -> 1 | E36: =SUM('생산 현황'!E88) -> 0.98039216 | G36: =B3 -> 12Lf-55PT-40 | I36: =SUMIF(불량유형!$A$43:$A$222,'Model별 품질현황'!$G$36,불량유형!B43:B222) -> 0 | J36: =SUMIF(불량유형!$A$43:$A$222,'Model별 품질현황'!$G$36,불량유형!C43:C222) -> 0 | K36: =SUMIF(불량유형!$A$43:$A$222,'Model별 품질현황'!$G$36,불량유형!D43:D222) -> 0 | L36: =SUMIF(불량유형!$A$43:$A$222,'Model별 품질현황'!$G$36,불량유형!E43:E222) -> 0 | M36: =SUMIF(불량유형!$A$43:$A$222,'Model별 품질현황'!$G$36,불량유형!F43:F222) -> 0 | N36: =SUMIF(불량유형!$A$43:$A$222,'Model별 품질현황'!$G$36,불량유형!G43:G222) -> 0 | O36: =SUMIF(불량유형!$A$43:$A$222,'Model별 품질현황'!$G$36,불량유형!H43:H222) -> 0 | P36: =SUMIF(불량유형!$A$43:$A$222,'Model별 품질현황'!$G$36,불량유형!I43:I222) -> 0 | ... AA36: =SUMIF(불량유형!$A$43:$A$222,'Model별 품질현황'!$G$36,불량유형!T43:T222) -> 0 | AB36: =SUM(I36:AA36) -> 5
A37: 73 | B37: L12-30F-4 | C37: =SUM('생산 현황'!C75) -> 103 | D37: =SUM('생산 현황'!D75) -> 1 | E37: =SUM('생산 현황'!E75) -> 0.97087379 | G37: =B4 -> 12Lf-17PT-53 | I37: =SUMIF(불량유형!$A$43:$A$222,'Model별 품질현황'!$G$37,불량유형!B43:B222) -> 0 | J37: =SUMIF(불량유형!$A$43:$A$222,'Model별 품질현황'!$G$37,불량유형!C43:C222) -> 0 | K37: =SUMIF(불량유형!$A$43:$A$222,'Model별 품질현황'!$G$37,불량유형!D43:D222) -> 0 | L37: =SUMIF(불량유형!$A$43:$A$222,'Model별 품질현황'!$G$37,불량유형!E43:E222) -> 0 | M37: =SUMIF(불량유형!$A$43:$A$222,'Model별 품질현황'!$G$37,불량유형!F43:F222) -> 0 | N37: =SUMIF(불량유형!$A$43:$A$222,'Model별 품질현황'!$G$37,불량유형!G43:G222) -> 0 | O37: =SUMIF(불량유형!$A$43:$A$222,'Model별 품질현황'!$G$37,불량유형!H43:H222) -> 0 | P37: =SUMIF(불량유형!$A$43:$A$222,'Model별 품질현황'!$G$37,불량유형!I43:I222) -> 2 | ... AA37: =SUMIF(불량유형!$A$43:$A$222,'Model별 품질현황'!$G$37,불량유형!T43:T222) -> 0 | AB37: =SUM(I37:AA37) -> 4
A38: 33 | B38: L12-20PT-3ES | C38: =SUM('생산 현황'!C35) -> 426 | D38: =SUM('생산 현황'!D35) -> 4 | E38: =SUM('생산 현황'!E35) -> 0.93896714 | G38: =B5 -> 12Lf-17PT-40 | I38: =SUMIF(불량유형!$A$43:$A$222,'Model별 품질현황'!$G$38,불량유형!B43:B222) -> 0 | J38: =SUMIF(불량유형!$A$43:$A$222,'Model별 품질현황'!$G$38,불량유형!C43:C222) -> 0 | K38: =SUMIF(불량유형!$A$43:$A$222,'Model별 품질현황'!$G$38,불량유형!D43:D222) -> 1 | L38: =SUMIF(불량유형!$A$43:$A$222,'Model별 품질현황'!$G$38,불량유형!E43:E222) -> 0 | M38: =SUMIF(불량유형!$A$43:$A$222,'Model별 품질현황'!$G$38,불량유형!F43:F222) -> 0 | N38: =SUMIF(불량유형!$A$43:$A$222,'Model별 품질현황'!$G$38,불량유형!G43:G222) -> 0 | O38: =SUMIF(불량유형!$A$43:$A$222,'Model별 품질현황'!$G$38,불량유형!H43:H222) -> 0 | P38: =SUMIF(불량유형!$A$43:$A$222,'Model별 품질현황'!$G$38,불량유형!I43:I222) -> 0 | ... AA38: =SUMIF(불량유형!$A$43:$A$222,'Model별 품질현황'!$G$38,불량유형!T43:T222) -> 0 | AB38: =SUM(I38:AA38) -> 3
A39: 42 | B39: 12Lf-20F-27 | C39: =SUM('생산 현황'!C44) -> 115 | D39: =SUM('생산 현황'!D44) -> 1 | E39: =SUM('생산 현황'!E44) -> 0.86956522 | G39: Total | I39: =SUM(I36:I38) -> 0 | J39: =SUM(J36:J38) -> 0 | K39: =SUM(K36:K38) -> 1 | L39: =SUM(L36:L38) -> 0 | M39: =SUM(M36:M38) -> 0 | N39: =SUM(N36:N38) -> 0 | O39: =SUM(O36:O38) -> 0 | P39: =SUM(P36:P38) -> 2 | ... AB39: =SUM(AB36:AB38) -> 12
A40: 45 | B40: 12Lf-12F-27 | C40: =SUM('생산 현황'!C47) -> 619 | D40: =SUM('생산 현황'!D47) -> 5 | E40: =SUM('생산 현황'!E47) -> 0.80775444 | G40: 점유 % | I40: =IFERROR(I39/AB39*100,"0") -> 0 | J40: =IFERROR(J39/AB39*100,"0") -> 0 | K40: =IFERROR(K39/AB39*100,"0") -> 8.3333333 | L40: =IFERROR(L39/AB39*100,"0") -> 0 | M40: =IFERROR(M39/AB39*100,"0") -> 0 | N40: =IFERROR(N39/AB39*100,"0") -> 0 | O40: =IFERROR(O39/AB39*100,"0") -> 0 | P40: =IFERROR(P39/AB39*100,"0") -> 16.666667 | Q40: =IFERROR(Q39/AB39*100,"0") -> 0 | R40: =IFERROR(R39/AB39*100,"0") -> 0 | S40: =IFERROR(S39/AB39*100,"0") -> 58.333333 | T40: =IFERROR(T39/AB39*100,"0") -> 0 | U40: =IFERROR(U39/AB39*100,"0") -> 0 | V40: =IFERROR(V39/AB39*100,"0") -> 0 | W40: =IFERROR(W39/AB39*100,"0") -> 0 | X40: =IFERROR(X39/AB39*100,"0") -> 16.666667 | Y40: =IFERROR(Y39/AB39*100,"0") -> 0 | Z40: =IFERROR(Z39/AB39*100,"0") -> 0 | AA40: =IFERROR(AA39/AB39*100,"0") -> 0 | AB40: =SUM(I40:AA40) -> 100
...

Sheet 불량유형
A1: 불량 유형
A2: 불량 명 | B2: Dead | C2: GC 200 | D2: LED | E2: Noise | F2: Straightness | G2: Speed | H2: Chattering | I2: Bounding | J2: Over Current | K2: IO Dead | L2: Stroke | M2: Slip | N2: Jitter | O2: CH Dead | P2: Screw missing | Q2: MP | R2: S/C | S2: Gap | T2: ETC | U2: 합계
A3: 불량 수 | B3: =B223 -> 18 | C3: =C223 -> 4 | D3: =D223 -> 7 | E3: =E223 -> 9 | F3: =F223 -> 2 | G3: =G223 -> 1 | H3: =H223 -> 2 | I3: =I223 -> 2 | ... T3: =T223 -> 2 | U3: =SUM(B3:T3) -> 116 | W3: #Cause of defect
A4: 점유 % | B4: =IFERROR(B3/U3*100,"0") -> 15.517241 | C4: =IFERROR(C3/U3*100,"0") -> 3.4482759 | D4: =IFERROR(D3/U3*100,"0") -> 6.0344828 | E4: =IFERROR(E3/U3*100,"0") -> 7.7586207 | F4: =IFERROR(F3/U3*100,"0") -> 1.7241379 | G4: =IFERROR(G3/U3*100,"0") -> 0.86206897 | H4: =IFERROR(H3/U3*100,"0") -> 1.7241379 | I4: =IFERROR(I3/U3*100,"0") -> 1.7241379 | J4: =IFERROR(J3/U3*100,"0") -> 6.8965517 | K4: =IFERROR(K3/U3*100,"0") -> 0.86206897 | L4: =IFERROR(L3/U3*100,"0") -> 25 | M4: =IFERROR(M3/U3*100,"0") -> 0.86206897 | N4: =IFERROR(N3/U3*100,"0") -> 1.7241379 | O4: =IFERROR(O3/U3*100,"0") -> 6.0344828 | P4: =IFERROR(P3/U3*100,"0") -> 1.7241379 | Q4: =IFERROR(Q3/U3*100,"0") -> 2.5862069 | R4: =IFERROR(R3/U3*100,"0") -> 1.7241379 | S4: =IFERROR(S3/U3*100,"0") -> 12.068966 | T4: =IFERROR(T3/U3*100,"0") -> 1.7241379 | U4: =SUM(B4:T4) -> 100
A5: 누적 | B5: =B4 -> 15.517241 | C5: =B5+C4 -> 18.965517 | D5: =C5+D4 -> 25 | E5: =D5+E4 -> 32.758621 | F5: =E5+F4 -> 34.482759 | G5: =F5+G4 -> 35.344828 | H5: =G5+H4 -> 37.068966 | I5: =H5+I4 -> 38.793103 | J5: =I5+J4 -> 45.689655 | ... T5: =S5+T4 -> 100
A7: 불량 명 | B7: =B2 -> Dead | C7: =C2 -> GC 200 | D7: =D2 -> LED | E7: =E2 -> Noise | F7: =F2 -> Straightness | G7: =G2 -> Speed | H7: =H2 -> Chattering | I7: =I2 -> Bounding | ... T7: =T2 -> ETC | U7: 합계
A8: 불량 수 | B8: =B3 -> 18 | C8: =C3 -> 4 | D8: =D3 -> 7 | E8: =E3 -> 9 | F8: =F3 -> 2 | G8: =G3 -> 1 | H8: =H3 -> 2 | I8: =I3 -> 2 | ... T8: =T3 -> 2 | U8: =SUM(B8:T8) -> 116
A9: 점유 % | B9: =B4 -> 15.517241 | C9: =C4 -> 3.4482759 | D9: =D4 -> 6.0344828 | E9: =E4 -> 7.7586207 | F9: =F4 -> 1.7241379 | G9: =G4 -> 0.86206897 | H9: =H4 -> 1.7241379 | I9: =I4 -> 1.7241379 | ... T9: =T4 -> 1.7241379 | U9: =SUM(B9:T9) -> 100
A10: 누적 | B10: =B5 -> 15.517241 | C10: =C5 -> 18.965517 | D10: =D5 -> 25 | E10: =E5 -> 32.758621 | F10: =F5 -> 34.482759 | G10: =G5 -> 35.344828 | H10: =H5 -> 37.068966 | I10: =I5 -> 38.793103 | ... T10: =T5 -> 100
A41: Model | B41: =B2 -> Dead | C41: =C2 -> GC 200 | D41: =D2 -> LED | E41: =E2 -> Noise | F41: =F2 -> Straightness | G41: =G2 -> Speed | H41: =H2 -> Chattering | I41: =I2 -> Bounding | ... U41: =U2 -> 합계
A43: LS2L-03EL | B43: ='1월'!AM9+'2월'!AM9+'3월'!AM9+'4월'!AM9+'5월'!AM9+'6월'!AM9+'7월'!AM9+'8월'!AM9+'9월'!AM9+'10월'!AM9+'11월'!AM9+'12월'!AM9 -> 0 | C43: ='1월'!AN9+'2월'!AN9+'3월'!AN9+'4월'!AN9+'5월'!AN9+'6월'!AN9+'7월'!AN9+'8월'!AN9+'9월'!AN9+'10월'!AN9+'11월'!AN9+'12월'!AN9 -> 0 | D43: ='1월'!AO9+'2월'!AO9+'3월'!AO9+'4월'!AO9+'5월'!AO9+'6월'!AO9+'7월'!AO9+'8월'!AO9+'9월'!AO9+'10월'!AO9+'11월'!AO9+'12월'!AO9 -> 0 | E43: ='1월'!AP9+'2월'!AP9+'3월'!AP9+'4월'!AP9+'5월'!AP9+'6월'!AP9+'7월'!AP9+'8월'!AP9+'9월'!AP9+'10월'!AP9+'11월'!AP9+'12월'!AP9 -> 0 | F43: ='1월'!AQ9+'2월'!AQ9+'3월'!AQ9+'4월'!AQ9+'5월'!AQ9+'6월'!AQ9+'7월'!AQ9+'8월'!AQ9+'9월'!AQ9+'10월'!AQ9+'11월'!AQ9+'12월'!AQ9 -> 0 | G43: ='1월'!AR9+'2월'!AR9+'3월'!AR9+'4월'!AR9+'5월'!AR9+'6월'!AR9+'7월'!AR9+'8월'!AR9+'9월'!AR9+'10월'!AR9+'11월'!AR9+'12월'!AR9 -> 0 | H43: ='1월'!AS9+'2월'!AS9+'3월'!AS9+'4월'!AS9+'5월'!AS9+'6월'!AS9+'7월'!AS9+'8월'!AS9+'9월'!AS9+'10월'!AS9+'11월'!AS9+'12월'!AS9 -> 0 | I43: ='1월'!AT9+'2월'!AT9+'3월'!AT9+'4월'!AT9+'5월'!AT9+'6월'!AT9+'7월'!AT9+'8월'!AT9+'9월'!AT9+'10월'!AT9+'11월'!AT9+'12월'!AT9 -> 0 | ... T43: ='1월'!BE9+'2월'!BE9+'3월'!BE9+'4월'!BE9+'5월'!BE9+'6월'!BE9+'7월'!BE9+'8월'!BE9+'9월'!BE9+'10월'!BE9+'11월'!BE9+'12월'!BE9 -> 0 | U43: =SUM(B43:T43) -> 0
A44: L7-6PT-3 | B44: ='1월'!AM10+'2월'!AM10+'3월'!AM10+'4월'!AM10+'5월'!AM10+'6월'!AM10+'7월'!AM10+'8월'!AM10+'9월'!AM10+'10월'!AM10+'11월'!AM10+'12월'!AM10 -> 0 | C44: ='1월'!AN10+'2월'!AN10+'3월'!AN10+'4월'!AN10+'5월'!AN10+'6월'!AN10+'7월'!AN10+'8월'!AN10+'9월'!AN10+'10월'!AN10+'11월'!AN10+'12월'!AN10 -> 0 | D44: ='1월'!AO10+'2월'!AO10+'3월'!AO10+'4월'!AO10+'5월'!AO10+'6월'!AO10+'7월'!AO10+'8월'!AO10+'9월'!AO10+'10월'!AO10+'11월'!AO10+'12월'!AO10 -> 0 | E44: ='1월'!AP10+'2월'!AP10+'3월'!AP10+'4월'!AP10+'5월'!AP10+'6월'!AP10+'7월'!AP10+'8월'!AP10+'9월'!AP10+'10월'!AP10+'11월'!AP10+'12월'!AP10 -> 0 | F44: ='1월'!AQ10+'2월'!AQ10+'3월'!AQ10+'4월'!AQ10+'5월'!AQ10+'6월'!AQ10+'7월'!AQ10+'8월'!AQ10+'9월'!AQ10+'10월'!AQ10+'11월'!AQ10+'12월'!AQ10 -> 0 | G44: ='1월'!AR10+'2월'!AR10+'3월'!AR10+'4월'!AR10+'5월'!AR10+'6월'!AR10+'7월'!AR10+'8월'!AR10+'9월'!AR10+'10월'!AR10+'11월'!AR10+'12월'!AR10 -> 0 | H44: ='1월'!AS10+'2월'!AS10+'3월'!AS10+'4월'!AS10+'5월'!AS10+'6월'!AS10+'7월'!AS10+'8월'!AS10+'9월'!AS10+'10월'!AS10+'11월'!AS10+'12월'!AS10 -> 0 | I44: ='1월'!AT10+'2월'!AT10+'3월'!AT10+'4월'!AT10+'5월'!AT10+'6월'!AT10+'7월'!AT10+'8월'!AT10+'9월'!AT10+'10월'!AT10+'11월'!AT10+'12월'!AT10 -> 0 | ... T44: ='1월'!BE10+'2월'!BE10+'3월'!BE10+'4월'!BE10+'5월'!BE10+'6월'!BE10+'7월'!BE10+'8월'!BE10+'9월'!BE10+'10월'!BE10+'11월'!BE10+'12월'!BE10 -> 0 | U44: =SUM(B44:T44) -> 0
A45: L7-12PT-3 | B45: ='1월'!AM11+'2월'!AM11+'3월'!AM11+'4월'!AM11+'5월'!AM11+'6월'!AM11+'7월'!AM11+'8월'!AM11+'9월'!AM11+'10월'!AM11+'11월'!AM11+'12월'!AM11 -> 0 | C45: ='1월'!AN11+'2월'!AN11+'3월'!AN11+'4월'!AN11+'5월'!AN11+'6월'!AN11+'7월'!AN11+'8월'!AN11+'9월'!AN11+'10월'!AN11+'11월'!AN11+'12월'!AN11 -> 0 | D45: ='1월'!AO11+'2월'!AO11+'3월'!AO11+'4월'!AO11+'5월'!AO11+'6월'!AO11+'7월'!AO11+'8월'!AO11+'9월'!AO11+'10월'!AO11+'11월'!AO11+'12월'!AO11 -> 0 | E45: ='1월'!AP11+'2월'!AP11+'3월'!AP11+'4월'!AP11+'5월'!AP11+'6월'!AP11+'7월'!AP11+'8월'!AP11+'9월'!AP11+'10월'!AP11+'11월'!AP11+'12월'!AP11 -> 0 | F45: ='1월'!AQ11+'2월'!AQ11+'3월'!AQ11+'4월'!AQ11+'5월'!AQ11+'6월'!AQ11+'7월'!AQ11+'8월'!AQ11+'9월'!AQ11+'10월'!AQ11+'11월'!AQ11+'12월'!AQ11 -> 0 | G45: ='1월'!AR11+'2월'!AR11+'3월'!AR11+'4월'!AR11+'5월'!AR11+'6월'!AR11+'7월'!AR11+'8월'!AR11+'9월'!AR11+'10월'!AR11+'11월'!AR11+'12월'!AR11 -> 0 | H45: ='1월'!AS11+'2월'!AS11+'3월'!AS11+'4월'!AS11+'5월'!AS11+'6월'!AS11+'7월'!AS11+'8월'!AS11+'9월'!AS11+'10월'!AS11+'11월'!AS11+'12월'!AS11 -> 0 | I45: ='1월'!AT11+'2월'!AT11+'3월'!AT11+'4월'!AT11+'5월'!AT11+'6월'!AT11+'7월'!AT11+'8월'!AT11+'9월'!AT11+'10월'!AT11+'11월'!AT11+'12월'!AT11 -> 0 | ... T45: ='1월'!BE11+'2월'!BE11+'3월'!BE11+'4월'!BE11+'5월'!BE11+'6월'!BE11+'7월'!BE11+'8월'!BE11+'9월'!BE11+'10월'!BE11+'11월'!BE11+'12월'!BE11 -> 0 | U45: =SUM(B45:T45) -> 0
A46: L7-13PT-3 | B46: ='1월'!AM12+'2월'!AM12+'3월'!AM12+'4월'!AM12+'5월'!AM12+'6월'!AM12+'7월'!AM12+'8월'!AM12+'9월'!AM12+'10월'!AM12+'11월'!AM12+'12월'!AM12 -> 0 | C46: ='1월'!AN12+'2월'!AN12+'3월'!AN12+'4월'!AN12+'5월'!AN12+'6월'!AN12+'7월'!AN12+'8월'!AN12+'9월'!AN12+'10월'!AN12+'11월'!AN12+'12월'!AN12 -> 0 | D46: ='1월'!AO12+'2월'!AO12+'3월'!AO12+'4월'!AO12+'5월'!AO12+'6월'!AO12+'7월'!AO12+'8월'!AO12+'9월'!AO12+'10월'!AO12+'11월'!AO12+'12월'!AO12 -> 0 | E46: ='1월'!AP12+'2월'!AP12+'3월'!AP12+'4월'!AP12+'5월'!AP12+'6월'!AP12+'7월'!AP12+'8월'!AP12+'9월'!AP12+'10월'!AP12+'11월'!AP12+'12월'!AP12 -> 0 | F46: ='1월'!AQ12+'2월'!AQ12+'3월'!AQ12+'4월'!AQ12+'5월'!AQ12+'6월'!AQ12+'7월'!AQ12+'8월'!AQ12+'9월'!AQ12+'10월'!AQ12+'11월'!AQ12+'12월'!AQ12 -> 0 | G46: ='1월'!AR12+'2월'!AR12+'3월'!AR12+'4월'!AR12+'5월'!AR12+'6월'!AR12+'7월'!AR12+'8월'!AR12+'9월'!AR12+'10월'!AR12+'11월'!AR12+'12월'!AR12 -> 0 | H46: ='1월'!AS12+'2월'!AS12+'3월'!AS12+'4월'!AS12+'5월'!AS12+'6월'!AS12+'7월'!AS12+'8월'!AS12+'9월'!AS12+'10월'!AS12+'11월'!AS12+'12월'!AS12 -> 0 | I46: ='1월'!AT12+'2월'!AT12+'3월'!AT12+'4월'!AT12+'5월'!AT12+'6월'!AT12+'7월'!AT12+'8월'!AT12+'9월'!AT12+'10월'!AT12+'11월'!AT12+'12월'!AT12 -> 0 | ... T46: ='1월'!BE12+'2월'!BE12+'3월'!BE12+'4월'!BE12+'5월'!BE12+'6월'!BE12+'7월'!BE12+'8월'!BE12+'9월'!BE12+'10월'!BE12+'11월'!BE12+'12월'!BE12 -> 0 | U46: =SUM(B46:T46) -> 0
A47: L7-20PT-3 | B47: ='1월'!AM13+'2월'!AM13+'3월'!AM13+'4월'!AM13+'5월'!AM13+'6월'!AM13+'7월'!AM13+'8월'!AM13+'9월'!AM13+'10월'!AM13+'11월'!AM13+'12월'!AM13 -> 0 | C47: ='1월'!AN13+'2월'!AN13+'3월'!AN13+'4월'!AN13+'5월'!AN13+'6월'!AN13+'7월'!AN13+'8월'!AN13+'9월'!AN13+'10월'!AN13+'11월'!AN13+'12월'!AN13 -> 0 | D47: ='1월'!AO13+'2월'!AO13+'3월'!AO13+'4월'!AO13+'5월'!AO13+'6월'!AO13+'7월'!AO13+'8월'!AO13+'9월'!AO13+'10월'!AO13+'11월'!AO13+'12월'!AO13 -> 0 | E47: ='1월'!AP13+'2월'!AP13+'3월'!AP13+'4월'!AP13+'5월'!AP13+'6월'!AP13+'7월'!AP13+'8월'!AP13+'9월'!AP13+'10월'!AP13+'11월'!AP13+'12월'!AP13 -> 0 | F47: ='1월'!AQ13+'2월'!AQ13+'3월'!AQ13+'4월'!AQ13+'5월'!AQ13+'6월'!AQ13+'7월'!AQ13+'8월'!AQ13+'9월'!AQ13+'10월'!AQ13+'11월'!AQ13+'12월'!AQ13 -> 0 | G47: ='1월'!AR13+'2월'!AR13+'3월'!AR13+'4월'!AR13+'5월'!AR13+'6월'!AR13+'7월'!AR13+'8월'!AR13+'9월'!AR13+'10월'!AR13+'11월'!AR13+'12월'!AR13 -> 0 | H47: ='1월'!AS13+'2월'!AS13+'3월'!AS13+'4월'!AS13+'5월'!AS13+'6월'!AS13+'7월'!AS13+'8월'!AS13+'9월'!AS13+'10월'!AS13+'11월'!AS13+'12월'!AS13 -> 0 | I47: ='1월'!AT13+'2월'!AT13+'3월'!AT13+'4월'!AT13+'5월'!AT13+'6월'!AT13+'7월'!AT13+'8월'!AT13+'9월'!AT13+'10월'!AT13+'11월'!AT13+'12월'!AT13 -> 0 | ... T47: ='1월'!BE13+'2월'!BE13+'3월'!BE13+'4월'!BE13+'5월'!BE13+'6월'!BE13+'7월'!BE13+'8월'!BE13+'9월'!BE13+'10월'!BE13+'11월'!BE13+'12월'!BE13 -> 0 | U47: =SUM(B47:T47) -> 0
A48: L7-40PT-3 | B48: ='1월'!AM14+'2월'!AM14+'3월'!AM14+'4월'!AM14+'5월'!AM14+'6월'!AM14+'7월'!AM14+'8월'!AM14+'9월'!AM14+'10월'!AM14+'11월'!AM14+'12월'!AM14 -> 0 | C48: ='1월'!AN14+'2월'!AN14+'3월'!AN14+'4월'!AN14+'5월'!AN14+'6월'!AN14+'7월'!AN14+'8월'!AN14+'9월'!AN14+'10월'!AN14+'11월'!AN14+'12월'!AN14 -> 0 | D48: ='1월'!AO14+'2월'!AO14+'3월'!AO14+'4월'!AO14+'5월'!AO14+'6월'!AO14+'7월'!AO14+'8월'!AO14+'9월'!AO14+'10월'!AO14+'11월'!AO14+'12월'!AO14 -> 0 | E48: ='1월'!AP14+'2월'!AP14+'3월'!AP14+'4월'!AP14+'5월'!AP14+'6월'!AP14+'7월'!AP14+'8월'!AP14+'9월'!AP14+'10월'!AP14+'11월'!AP14+'12월'!AP14 -> 0 | F48: ='1월'!AQ14+'2월'!AQ14+'3월'!AQ14+'4월'!AQ14+'5월'!AQ14+'6월'!AQ14+'7월'!AQ14+'8월'!AQ14+'9월'!AQ14+'10월'!AQ14+'11월'!AQ14+'12월'!AQ14 -> 0 | G48: ='1월'!AR14+'2월'!AR14+'3월'!AR14+'4월'!AR14+'5월'!AR14+'6월'!AR14+'7월'!AR14+'8월'!AR14+'9월'!AR14+'10월'!AR14+'11월'!AR14+'12월'!AR14 -> 0 | H48: ='1월'!AS14+'2월'!AS14+'3월'!AS14+'4월'!AS14+'5월'!AS14+'6월'!AS14+'7월'!AS14+'8월'!AS14+'9월'!AS14+'10월'!AS14+'11월'!AS14+'12월'!AS14 -> 0 | I48: ='1월'!AT14+'2월'!AT14+'3월'!AT14+'4월'!AT14+'5월'!AT14+'6월'!AT14+'7월'!AT14+'8월'!AT14+'9월'!AT14+'10월'!AT14+'11월'!AT14+'12월'!AT14 -> 0 | ... T48: ='1월'!BE14+'2월'!BE14+'3월'!BE14+'4월'!BE14+'5월'!BE14+'6월'!BE14+'7월'!BE14+'8월'!BE14+'9월'!BE14+'10월'!BE14+'11월'!BE14+'12월'!BE14 -> 0 | U48: =SUM(B48:T48) -> 0
A49: L7-64PT-3 | B49: ='1월'!AM15+'2월'!AM15+'3월'!AM15+'4월'!AM15+'5월'!AM15+'6월'!AM15+'7월'!AM15+'8월'!AM15+'9월'!AM15+'10월'!AM15+'11월'!AM15+'12월'!AM15 -> 0 | C49: ='1월'!AN15+'2월'!AN15+'3월'!AN15+'4월'!AN15+'5월'!AN15+'6월'!AN15+'7월'!AN15+'8월'!AN15+'9월'!AN15+'10월'!AN15+'11월'!AN15+'12월'!AN15 -> 0 | D49: ='1월'!AO15+'2월'!AO15+'3월'!AO15+'4월'!AO15+'5월'!AO15+'6월'!AO15+'7월'!AO15+'8월'!AO15+'9월'!AO15+'10월'!AO15+'11월'!AO15+'12월'!AO15 -> 0 | E49: ='1월'!AP15+'2월'!AP15+'3월'!AP15+'4월'!AP15+'5월'!AP15+'6월'!AP15+'7월'!AP15+'8월'!AP15+'9월'!AP15+'10월'!AP15+'11월'!AP15+'12월'!AP15 -> 0 | F49: ='1월'!AQ15+'2월'!AQ15+'3월'!AQ15+'4월'!AQ15+'5월'!AQ15+'6월'!AQ15+'7월'!AQ15+'8월'!AQ15+'9월'!AQ15+'10월'!AQ15+'11월'!AQ15+'12월'!AQ15 -> 0 | G49: ='1월'!AR15+'2월'!AR15+'3월'!AR15+'4월'!AR15+'5월'!AR15+'6월'!AR15+'7월'!AR15+'8월'!AR15+'9월'!AR15+'10월'!AR15+'11월'!AR15+'12월'!AR15 -> 0 | H49: ='1월'!AS15+'2월'!AS15+'3월'!AS15+'4월'!AS15+'5월'!AS15+'6월'!AS15+'7월'!AS15+'8월'!AS15+'9월'!AS15+'10월'!AS15+'11월'!AS15+'12월'!AS15 -> 0 | I49: ='1월'!AT15+'2월'!AT15+'3월'!AT15+'4월'!AT15+'5월'!AT15+'6월'!AT15+'7월'!AT15+'8월'!AT15+'9월'!AT15+'10월'!AT15+'11월'!AT15+'12월'!AT15 -> 0 | ... T49: ='1월'!BE15+'2월'!BE15+'3월'!BE15+'4월'!BE15+'5월'!BE15+'6월'!BE15+'7월'!BE15+'8월'!BE15+'9월'!BE15+'10월'!BE15+'11월'!BE15+'12월'!BE15 -> 0 | U49: =SUM(B49:T49) -> 0
A50: L7-100PT-3 | B50: ='1월'!AM16+'2월'!AM16+'3월'!AM16+'4월'!AM16+'5월'!AM16+'6월'!AM16+'7월'!AM16+'8월'!AM16+'9월'!AM16+'10월'!AM16+'11월'!AM16+'12월'!AM16 -> 0 | C50: ='1월'!AN16+'2월'!AN16+'3월'!AN16+'4월'!AN16+'5월'!AN16+'6월'!AN16+'7월'!AN16+'8월'!AN16+'9월'!AN16+'10월'!AN16+'11월'!AN16+'12월'!AN16 -> 0 | D50: ='1월'!AO16+'2월'!AO16+'3월'!AO16+'4월'!AO16+'5월'!AO16+'6월'!AO16+'7월'!AO16+'8월'!AO16+'9월'!AO16+'10월'!AO16+'11월'!AO16+'12월'!AO16 -> 0 | E50: ='1월'!AP16+'2월'!AP16+'3월'!AP16+'4월'!AP16+'5월'!AP16+'6월'!AP16+'7월'!AP16+'8월'!AP16+'9월'!AP16+'10월'!AP16+'11월'!AP16+'12월'!AP16 -> 0 | F50: ='1월'!AQ16+'2월'!AQ16+'3월'!AQ16+'4월'!AQ16+'5월'!AQ16+'6월'!AQ16+'7월'!AQ16+'8월'!AQ16+'9월'!AQ16+'10월'!AQ16+'11월'!AQ16+'12월'!AQ16 -> 0 | G50: ='1월'!AR16+'2월'!AR16+'3월'!AR16+'4월'!AR16+'5월'!AR16+'6월'!AR16+'7월'!AR16+'8월'!AR16+'9월'!AR16+'10월'!AR16+'11월'!AR16+'12월'!AR16 -> 0 | H50: ='1월'!AS16+'2월'!AS16+'3월'!AS16+'4월'!AS16+'5월'!AS16+'6월'!AS16+'7월'!AS16+'8월'!AS16+'9월'!AS16+'10월'!AS16+'11월'!AS16+'12월'!AS16 -> 0 | I50: ='1월'!AT16+'2월'!AT16+'3월'!AT16+'4월'!AT16+'5월'!AT16+'6월'!AT16+'7월'!AT16+'8월'!AT16+'9월'!AT16+'10월'!AT16+'11월'!AT16+'12월'!AT16 -> 0 | ... T50: ='1월'!BE16+'2월'!BE16+'3월'!BE16+'4월'!BE16+'5월'!BE16+'6월'!BE16+'7월'!BE16+'8월'!BE16+'9월'!BE16+'10월'!BE16+'11월'!BE16+'12월'!BE16 -> 0 | U50: =SUM(B50:T50) -> 0
A51: L12-6PT-3 | B51: ='1월'!AM17+'2월'!AM17+'3월'!AM17+'4월'!AM17+'5월'!AM17+'6월'!AM17+'7월'!AM17+'8월'!AM17+'9월'!AM17+'10월'!AM17+'11월'!AM17+'12월'!AM17 -> 0 | C51: ='1월'!AN17+'2월'!AN17+'3월'!AN17+'4월'!AN17+'5월'!AN17+'6월'!AN17+'7월'!AN17+'8월'!AN17+'9월'!AN17+'10월'!AN17+'11월'!AN17+'12월'!AN17 -> 0 | D51: ='1월'!AO17+'2월'!AO17+'3월'!AO17+'4월'!AO17+'5월'!AO17+'6월'!AO17+'7월'!AO17+'8월'!AO17+'9월'!AO17+'10월'!AO17+'11월'!AO17+'12월'!AO17 -> 0 | E51: ='1월'!AP17+'2월'!AP17+'3월'!AP17+'4월'!AP17+'5월'!AP17+'6월'!AP17+'7월'!AP17+'8월'!AP17+'9월'!AP17+'10월'!AP17+'11월'!AP17+'12월'!AP17 -> 0 | F51: ='1월'!AQ17+'2월'!AQ17+'3월'!AQ17+'4월'!AQ17+'5월'!AQ17+'6월'!AQ17+'7월'!AQ17+'8월'!AQ17+'9월'!AQ17+'10월'!AQ17+'11월'!AQ17+'12월'!AQ17 -> 0 | G51: ='1월'!AR17+'2월'!AR17+'3월'!AR17+'4월'!AR17+'5월'!AR17+'6월'!AR17+'7월'!AR17+'8월'!AR17+'9월'!AR17+'10월'!AR17+'11월'!AR17+'12월'!AR17 -> 0 | H51: ='1월'!AS17+'2월'!AS17+'3월'!AS17+'4월'!AS17+'5월'!AS17+'6월'!AS17+'7월'!AS17+'8월'!AS17+'9월'!AS17+'10월'!AS17+'11월'!AS17+'12월'!AS17 -> 0 | I51: ='1월'!AT17+'2월'!AT17+'3월'!AT17+'4월'!AT17+'5월'!AT17+'6월'!AT17+'7월'!AT17+'8월'!AT17+'9월'!AT17+'10월'!AT17+'11월'!AT17+'12월'!AT17 -> 0 | ... T51: ='1월'!BE17+'2월'!BE17+'3월'!BE17+'4월'!BE17+'5월'!BE17+'6월'!BE17+'7월'!BE17+'8월'!BE17+'9월'!BE17+'10월'!BE17+'11월'!BE17+'12월'!BE17 -> 0 | U51: =SUM(B51:T51) -> 0
A52: L12-12PT-3 | B52: ='1월'!AM18+'2월'!AM18+'3월'!AM18+'4월'!AM18+'5월'!AM18+'6월'!AM18+'7월'!AM18+'8월'!AM18+'9월'!AM18+'10월'!AM18+'11월'!AM18+'12월'!AM18 -> 0 | C52: ='1월'!AN18+'2월'!AN18+'3월'!AN18+'4월'!AN18+'5월'!AN18+'6월'!AN18+'7월'!AN18+'8월'!AN18+'9월'!AN18+'10월'!AN18+'11월'!AN18+'12월'!AN18 -> 0 | D52: ='1월'!AO18+'2월'!AO18+'3월'!AO18+'4월'!AO18+'5월'!AO18+'6월'!AO18+'7월'!AO18+'8월'!AO18+'9월'!AO18+'10월'!AO18+'11월'!AO18+'12월'!AO18 -> 0 | E52: ='1월'!AP18+'2월'!AP18+'3월'!AP18+'4월'!AP18+'5월'!AP18+'6월'!AP18+'7월'!AP18+'8월'!AP18+'9월'!AP18+'10월'!AP18+'11월'!AP18+'12월'!AP18 -> 0 | F52: ='1월'!AQ18+'2월'!AQ18+'3월'!AQ18+'4월'!AQ18+'5월'!AQ18+'6월'!AQ18+'7월'!AQ18+'8월'!AQ18+'9월'!AQ18+'10월'!AQ18+'11월'!AQ18+'12월'!AQ18 -> 0 | G52: ='1월'!AR18+'2월'!AR18+'3월'!AR18+'4월'!AR18+'5월'!AR18+'6월'!AR18+'7월'!AR18+'8월'!AR18+'9월'!AR18+'10월'!AR18+'11월'!AR18+'12월'!AR18 -> 0 | H52: ='1월'!AS18+'2월'!AS18+'3월'!AS18+'4월'!AS18+'5월'!AS18+'6월'!AS18+'7월'!AS18+'8월'!AS18+'9월'!AS18+'10월'!AS18+'11월'!AS18+'12월'!AS18 -> 0 | I52: ='1월'!AT18+'2월'!AT18+'3월'!AT18+'4월'!AT18+'5월'!AT18+'6월'!AT18+'7월'!AT18+'8월'!AT18+'9월'!AT18+'10월'!AT18+'11월'!AT18+'12월'!AT18 -> 0 | ... T52: ='1월'!BE18+'2월'!BE18+'3월'!BE18+'4월'!BE18+'5월'!BE18+'6월'!BE18+'7월'!BE18+'8월'!BE18+'9월'!BE18+'10월'!BE18+'11월'!BE18+'12월'!BE18 -> 0 | U52: =SUM(B52:T52) -> 0
A53: L12-13PT-3 | B53: ='1월'!AM19+'2월'!AM19+'3월'!AM19+'4월'!AM19+'5월'!AM19+'6월'!AM19+'7월'!AM19+'8월'!AM19+'9월'!AM19+'10월'!AM19+'11월'!AM19+'12월'!AM19 -> 0 | C53: ='1월'!AN19+'2월'!AN19+'3월'!AN19+'4월'!AN19+'5월'!AN19+'6월'!AN19+'7월'!AN19+'8월'!AN19+'9월'!AN19+'10월'!AN19+'11월'!AN19+'12월'!AN19 -> 0 | D53: ='1월'!AO19+'2월'!AO19+'3월'!AO19+'4월'!AO19+'5월'!AO19+'6월'!AO19+'7월'!AO19+'8월'!AO19+'9월'!AO19+'10월'!AO19+'11월'!AO19+'12월'!AO19 -> 0 | E53: ='1월'!AP19+'2월'!AP19+'3월'!AP19+'4월'!AP19+'5월'!AP19+'6월'!AP19+'7월'!AP19+'8월'!AP19+'9월'!AP19+'10월'!AP19+'11월'!AP19+'12월'!AP19 -> 0 | F53: ='1월'!AQ19+'2월'!AQ19+'3월'!AQ19+'4월'!AQ19+'5월'!AQ19+'6월'!AQ19+'7월'!AQ19+'8월'!AQ19+'9월'!AQ19+'10월'!AQ19+'11월'!AQ19+'12월'!AQ19 -> 0 | G53: ='1월'!AR19+'2월'!AR19+'3월'!AR19+'4월'!AR19+'5월'!AR19+'6월'!AR19+'7월'!AR19+'8월'!AR19+'9월'!AR19+'10월'!AR19+'11월'!AR19+'12월'!AR19 -> 0 | H53: ='1월'!AS19+'2월'!AS19+'3월'!AS19+'4월'!AS19+'5월'!AS19+'6월'!AS19+'7월'!AS19+'8월'!AS19+'9월'!AS19+'10월'!AS19+'11월'!AS19+'12월'!AS19 -> 0 | I53: ='1월'!AT19+'2월'!AT19+'3월'!AT19+'4월'!AT19+'5월'!AT19+'6월'!AT19+'7월'!AT19+'8월'!AT19+'9월'!AT19+'10월'!AT19+'11월'!AT19+'12월'!AT19 -> 0 | ... T53: ='1월'!BE19+'2월'!BE19+'3월'!BE19+'4월'!BE19+'5월'!BE19+'6월'!BE19+'7월'!BE19+'8월'!BE19+'9월'!BE19+'10월'!BE19+'11월'!BE19+'12월'!BE19 -> 0 | U53: =SUM(B53:T53) -> 0
A54: L12-20PT-3 | B54: ='1월'!AM20+'2월'!AM20+'3월'!AM20+'4월'!AM20+'5월'!AM20+'6월'!AM20+'7월'!AM20+'8월'!AM20+'9월'!AM20+'10월'!AM20+'11월'!AM20+'12월'!AM20 -> 0 | C54: ='1월'!AN20+'2월'!AN20+'3월'!AN20+'4월'!AN20+'5월'!AN20+'6월'!AN20+'7월'!AN20+'8월'!AN20+'9월'!AN20+'10월'!AN20+'11월'!AN20+'12월'!AN20 -> 0 | D54: ='1월'!AO20+'2월'!AO20+'3월'!AO20+'4월'!AO20+'5월'!AO20+'6월'!AO20+'7월'!AO20+'8월'!AO20+'9월'!AO20+'10월'!AO20+'11월'!AO20+'12월'!AO20 -> 0 | E54: ='1월'!AP20+'2월'!AP20+'3월'!AP20+'4월'!AP20+'5월'!AP20+'6월'!AP20+'7월'!AP20+'8월'!AP20+'9월'!AP20+'10월'!AP20+'11월'!AP20+'12월'!AP20 -> 0 | F54: ='1월'!AQ20+'2월'!AQ20+'3월'!AQ20+'4월'!AQ20+'5월'!AQ20+'6월'!AQ20+'7월'!AQ20+'8월'!AQ20+'9월'!AQ20+'10월'!AQ20+'11월'!AQ20+'12월'!AQ20 -> 0 | G54: ='1월'!AR20+'2월'!AR20+'3월'!AR20+'4월'!AR20+'5월'!AR20+'6월'!AR20+'7월'!AR20+'8월'!AR20+'9월'!AR20+'10월'!AR20+'11월'!AR20+'12월'!AR20 -> 0 | H54: ='1월'!AS20+'2월'!AS20+'3월'!AS20+'4월'!AS20+'5월'!AS20+'6월'!AS20+'7월'!AS20+'8월'!AS20+'9월'!AS20+'10월'!AS20+'11월'!AS20+'12월'!AS20 -> 0 | I54: ='1월'!AT20+'2월'!AT20+'3월'!AT20+'4월'!AT20+'5월'!AT20+'6월'!AT20+'7월'!AT20+'8월'!AT20+'9월'!AT20+'10월'!AT20+'11월'!AT20+'12월'!AT20 -> 0 | ... T54: ='1월'!BE20+'2월'!BE20+'3월'!BE20+'4월'!BE20+'5월'!BE20+'6월'!BE20+'7월'!BE20+'8월'!BE20+'9월'!BE20+'10월'!BE20+'11월'!BE20+'12월'!BE20 -> 0 | U54: =SUM(B54:T54) -> 0
... A222: IR-IM02 | B222: ='1월'!AM188+'2월'!AM188+'3월'!AM188+'4월'!AM188+'5월'!AM188+'6월'!AM188+'7월'!AM188+'8월'!AM188+'9월'!AM188+'10월'!AM188+'11월'!AM188+'12월'!AM188 -> 0 | C222: ='1월'!AN188+'2월'!AN188+'3월'!AN188+'4월'!AN188+'5월'!AN188+'6월'!AN188+'7월'!AN188+'8월'!AN188+'9월'!AN188+'10월'!AN188+'11월'!AN188+'12월'!AN188 -> 0 | D222: ='1월'!AO188+'2월'!AO188+'3월'!AO188+'4월'!AO188+'5월'!AO188+'6월'!AO188+'7월'!AO188+'8월'!AO188+'9월'!AO188+'10월'!AO188+'11월'!AO188+'12월'!AO188 -> 0 | E222: ='1월'!AP188+'2월'!AP188+'3월'!AP188+'4월'!AP188+'5월'!AP188+'6월'!AP188+'7월'!AP188+'8월'!AP188+'9월'!AP188+'10월'!AP188+'11월'!AP188+'12월'!AP188 -> 0 | F222: ='1월'!AQ188+'2월'!AQ188+'3월'!AQ188+'4월'!AQ188+'5월'!AQ188+'6월'!AQ188+'7월'!AQ188+'8월'!AQ188+'9월'!AQ188+'10월'!AQ188+'11월'!AQ188+'12월'!AQ188 -> 0 | G222: ='1월'!AR188+'2월'!AR188+'3월'!AR188+'4월'!AR188+'5월'!AR188+'6월'!AR188+'7월'!AR188+'8월'!AR188+'9월'!AR188+'10월'!AR188+'11월'!AR188+'12월'!AR188 -> 0 | H222: ='1월'!AS188+'2월'!AS188+'3월'!AS188+'4월'!AS188+'5월'!AS188+'6월'!AS188+'7월'!AS188+'8월'!AS188+'9월'!AS188+'10월'!AS188+'11월'!AS188+'12월'!AS188 -> 0 | I222: ='1월'!AT188+'2월'!AT188+'3월'!AT188+'4월'!AT188+'5월'!AT188+'6월'!AT188+'7월'!AT188+'8월'!AT188+'9월'!AT188+'10월'!AT188+'11월'!AT188+'12월'!AT188 -> 0 | ... T222: ='1월'!BE188+'2월'!BE188+'3월'!BE188+'4월'!BE188+'5월'!BE188+'6월'!BE188+'7월'!BE188+'8월'!BE188+'9월'!BE188+'10월'!BE188+'11월'!BE188+'12월'!BE188 -> 0 | U222: =SUM(B222:T222) -> 0
B223: =SUM(B43:B222) -> 18 | C223: =SUM(C43:C222) -> 4 | D223: =SUM(D43:D222) -> 7 | E223: =SUM(E43:E222) -> 9 | F223: =SUM(F43:F222) -> 2 | G223: =SUM(G43:G222) -> 1 | H223: =SUM(H43:H222) -> 2 | I223: =SUM(I43:I222) -> 2 | ... T223: =SUM(T43:T222) -> 2 | U223: =SUM(B223:T223) -> 116

Sheet 생산 현황
A2: No. | B2: Model | C2: 검사 수[EA] | D2: 불량 수[EA] | E2: 불량[%] | H2: 1월 | I2: 2월 | J2: 3월 | K2: 4월 | L2: 5월 | M2: 6월 | N2: 7월 | O2: 8월 | P2: 9월 | Q2: 10월 | R2: 11월 | S2: 12월 | T2: 합계
A3: 1 | B3: LS2L-03EL | C3: ='1월'!AH8+'2월'!AH8+'3월'!AH8+'4월'!AH8+'5월'!AH8+'6월'!AH8+'7월'!AH8+'8월'!AH8+'9월'!AH8+'10월'!AH8+'11월'!AH8+'12월'!AH8 -> 0 | D3: ='1월'!AI8+'2월'!AI8+'3월'!AI8+'4월'!AI8+'5월'!AI8+'6월'!AI8+'7월'!AI8+'8월'!AI8+'9월'!AI8+'10월'!AI8+'11월'!AI8+'12월'!AI8 -> 0 | E3: =IFERROR(D3*100/C3,"0") -> 0 | G3: 검사 수 | H3: ='월 품질 현황'!C3 -> 548 | I3: ='월 품질 현황'!D3 -> 415 | J3: ='월 품질 현황'!E3 -> 712 | K3: ='월 품질 현황'!F3 -> 836 | L3: ='월 품질 현황'!G3 -> 821 | M3: ='월 품질 현황'!H3 -> 1013 | N3: ='월 품질 현황'!I3 -> 968 | O3: ='월 품질 현황'!J3 -> 868 | ... S3: ='월 품질 현황'!N3 -> 413 | T3: =SUM(H3:S3) -> 8540
A4: 2 | B4: L7-6PT-3 | C4: ='1월'!AH9+'2월'!AH9+'3월'!AH9+'4월'!AH9+'5월'!AH9+'6월'!AH9+'7월'!AH9+'8월'!AH9+'9월'!AH9+'10월'!AH9+'11월'!AH9+'12월'!AH9 -> 0 | D4: ='1월'!AI9+'2월'!AI9+'3월'!AI9+'4월'!AI9+'5월'!AI9+'6월'!AI9+'7월'!AI9+'8월'!AI9+'9월'!AI9+'10월'!AI9+'11월'!AI9+'12월'!AI9 -> 0 | E4: =IFERROR(D4*100/C4,"0") -> 0 | G4: 불량 수 | H4: ='1월'!F3 -> 15 | I4: ='2월'!F3 -> 18 | J4: ='3월'!F3 -> 17 | K4: ='4월'!F3 -> 8 | L4: ='5월'!F3 -> 12 | M4: ='6월'!F3 -> 7 | N4: ='7월'!F3 -> 7 | O4: ='8월'!F3 -> 6 | P4: ='9월'!F3 -> 11 | Q4: ='10월'!F3 -> 7 | R4: ='11월'!F3 -> 5 | S4: ='12월'!F3 -> 2 | T4: =SUM(H4:S4) -> 115
A5: 3 | B5: L7-12PT-3 | C5: ='1월'!AH10+'2월'!AH10+'3월'!AH10+'4월'!AH10+'5월'!AH10+'6월'!AH10+'7월'!AH10+'8월'!AH10+'9월'!AH10+'10월'!AH10+'11월'!AH10+'12월'!AH10 -> 0 | D5: ='1월'!AI10+'2월'!AI10+'3월'!AI10+'4월'!AI10+'5월'!AI10+'6월'!AI10+'7월'!AI10+'8월'!AI10+'9월'!AI10+'10월'!AI10+'11월'!AI10+'12월'!AI10 -> 0 | E5: =IFERROR(D5*100/C5,"0") -> 0 | G5: 양품 수(실적) | H5: =H3-H4 -> 533 | I5: =I3-I4 -> 397 | J5: =J3-J4 -> 695 | K5: =K3-K4 -> 828 | L5: =L3-L4 -> 809 | M5: =M3-M4 -> 1006 | N5: =N3-N4 -> 961 | O5: =O3-O4 -> 862 | ... S5: =S3-S4 -> 411 | T5: =SUM(H5:S5) -> 8425
A6: 4 | B6: L7-13PT-3 | C6: ='1월'!AH11+'2월'!AH11+'3월'!AH11+'4월'!AH11+'5월'!AH11+'6월'!AH11+'7월'!AH11+'8월'!AH11+'9월'!AH11+'10월'!AH11+'11월'!AH11+'12월'!AH11 -> 0 | D6: ='1월'!AI11+'2월'!AI11+'3월'!AI11+'4월'!AI11+'5월'!AI11+'6월'!AI11+'7월'!AI11+'8월'!AI11+'9월'!AI11+'10월'!AI11+'11월'!AI11+'12월'!AI11 -> 0 | E6: =IFERROR(D6*100/C6,"0") -> 0 | G6: 불량 % | H6: =IFERROR((H4*100/H3),"0") -> 2.7372263 | I6: =IFERROR((I4*100/I3),"0") -> 4.3373494 | J6: =IFERROR((J4*100/J3),"0") -> 2.3876404 | K6: =IFERROR((K4*100/K3),"0") -> 0.9569378 | L6: =IFERROR((L4*100/L3),"0") -> 1.4616322 | M6: =IFERROR((M4*100/M3),"0") -> 0.69101678 | N6: =IFERROR((N4*100/N3),"0") -> 0.7231405 | O6: =IFERROR((O4*100/O3),"0") -> 0.69124424 | ... S6: =IFERROR((S4*100/S3),"0") -> 0.4842615 | T6: =T4*100/T3 -> 1.3466042
A7: 5 | B7: L7-20PT-3 | C7: ='1월'!AH12+'2월'!AH12+'3월'!AH12+'4월'!AH12+'5월'!AH12+'6월'!AH12+'7월'!AH12+'8월'!AH12+'9월'!AH12+'10월'!AH12+'11월'!AH12+'12월'!AH12 -> 0 | D7: ='1월'!AI12+'2월'!AI12+'3월'!AI12+'4월'!AI12+'5월'!AI12+'6월'!AI12+'7월'!AI12+'8월'!AI12+'9월'!AI12+'10월'!AI12+'11월'!AI12+'12월'!AI12 -> 0 | E7: =IFERROR(D7*100/C7,"0") -> 0 | G7: 작업일수(일) | H7: =가동율!AM5 -> 17 | I7: =가동율!AM6 -> 20 | J7: =가동율!AM7 -> 20 | K7: =가동율!AM8 -> 22 | L7: =가동율!AM9 -> 18 | M7: =가동율!AM10 -> 19 | N7: =가동율!AM11 -> 21 | O7: =가동율!AM12 -> 19 | P7: =가동율!AM13 -> 22 | Q7: =가동율!AM14 -> 17 | R7: =가동율!AM15 -> 20 | S7: =가동율!AM16 -> 21 | T7: =SUM(H7:S7) -> 236
A8: 6 | B8: L7-40PT-3 | C8: ='1월'!AH13+'2월'!AH13+'3월'!AH13+'4월'!AH13+'5월'!AH13+'6월'!AH13+'7월'!AH13+'8월'!AH13+'9월'!AH13+'10월'!AH13+'11월'!AH13+'12월'!AH13 -> 0 | D8: ='1월'!AI13+'2월'!AI13+'3월'!AI13+'4월'!AI13+'5월'!AI13+'6월'!AI13+'7월'!AI13+'8월'!AI13+'9월'!AI13+'10월'!AI13+'11월'!AI13+'12월'!AI13 -> 0 | E8: =IFERROR(D8*100/C8,"0") -> 0 | G8: 생산 인원(人) | H8: 2 | I8: 2 | J8: 2 | K8: 2 | L8: 2 | M8: 2 | N8: 2 | O8: 2 | P8: 2 | Q8: 2 | R8: 2 | S8: 2 | T8: =SUM(H8:S8) -> 24
A9: 7 | B9: L7-64PT-3 | C9: ='1월'!AH14+'2월'!AH14+'3월'!AH14+'4월'!AH14+'5월'!AH14+'6월'!AH14+'7월'!AH14+'8월'!AH14+'9월'!AH14+'10월'!AH14+'11월'!AH14+'12월'!AH14 -> 0 | D9: ='1월'!AI14+'2월'!AI14+'3월'!AI14+'4월'!AI14+'5월'!AI14+'6월'!AI14+'7월'!AI14+'8월'!AI14+'9월'!AI14+'10월'!AI14+'11월'!AI14+'12월'!AI14 -> 0 | E9: =IFERROR(D9*100/C9,"0") -> 0 | G9: 월 별 Capa 인원(人) | H9: =H10*H7 -> 32.75 | I9: =I10*I7 -> 39 | J9: =J10*J7 -> 39 | K9: =K10*K7 -> 40.5 | L9: =L10*L7 -> 36 | M9: =M10*M7 -> 38 | N9: =N10*N7 -> 42 | O9: =O10*O7 -> 37 | ... S9: =S10*S7 -> 38.75 | T9: =SUM(H9:S9) -> 457.5
A10: 8 | B10: L7-100PT-3 | C10: ='1월'!AH15+'2월'!AH15+'3월'!AH15+'4월'!AH15+'5월'!AH15+'6월'!AH15+'7월'!AH15+'8월'!AH15+'9월'!AH15+'10월'!AH15+'11월'!AH15+'12월'!AH15 -> 0 | D10: ='1월'!AI15+'2월'!AI15+'3월'!AI15+'4월'!AI15+'5월'!AI15+'6월'!AI15+'7월'!AI15+'8월'!AI15+'9월'!AI15+'10월'!AI15+'11월'!AI15+'12월'!AI15 -> 0 | E10: =IFERROR(D10*100/C10,"0") -> 0 | G10: 일일 평균 작업 인원 | H10: =가동율!AL5 -> 1.9264706 | I10: =가동율!AL6 -> 1.95 | J10: =가동율!AL7 -> 1.95 | K10: =가동율!AL8 -> 1.8409091 | L10: =가동율!AL9 -> 2 | M10: =가동율!AL10 -> 2 | N10: =가동율!AL11 -> 2 | O10: =가동율!AL12 -> 1.9473684 | P10: =가동율!AL13 -> 2 | Q10: =가동율!AL14 -> 1.8823529 | R10: =가동율!AL15 -> 1.925 | S10: =가동율!AL16 -> 1.8452381 | T10: =T9/T7 -> 1.9385593
A11: 9 | B11: L12-6PT-3 | C11: ='1월'!AH16+'2월'!AH16+'3월'!AH16+'4월'!AH16+'5월'!AH16+'6월'!AH16+'7월'!AH16+'8월'!AH16+'9월'!AH16+'10월'!AH16+'11월'!AH16+'12월'!AH16 -> 0 | D11: ='1월'!AI16+'2월'!AI16+'3월'!AI16+'4월'!AI16+'5월'!AI16+'6월'!AI16+'7월'!AI16+'8월'!AI16+'9월'!AI16+'10월'!AI16+'11월'!AI16+'12월'!AI16 -> 0 | E11: =IFERROR(D11*100/C11,"0") -> 0 | G11: 가동[%] | H11: =가동율!AN5 -> 96.323529 | I11: =가동율!AN6 -> 97.5 | J11: =가동율!AN7 -> 97.5 | K11: =가동율!AN8 -> 92.045455 | L11: =가동율!AN9 -> 100 | M11: =가동율!AN10 -> 100 | N11: =가동율!AN11 -> 100 | O11: =가동율!AN12 -> 97.368421 | P11: =가동율!AN13 -> 100 | Q11: =가동율!AN14 -> 94.117647 | R11: =가동율!AN15 -> 96.25 | S11: =가동율!AN16 -> 92.261905 | T11: =가동율!AK17*100/가동율!AJ17 -> 96.927966
A12: 10 | B12: L12-12PT-3 | C12: ='1월'!AH17+'2월'!AH17+'3월'!AH17+'4월'!AH17+'5월'!AH17+'6월'!AH17+'7월'!AH17+'8월'!AH17+'9월'!AH17+'10월'!AH17+'11월'!AH17+'12월'!AH17 -> 0 | D12: ='1월'!AI17+'2월'!AI17+'3월'!AI17+'4월'!AI17+'5월'!AI17+'6월'!AI17+'7월'!AI17+'8월'!AI17+'9월'!AI17+'10월'!AI17+'11월'!AI17+'12월'!AI17 -> 0 | E12: =IFERROR(D12*100/C12,"0") -> 0 | G12: 월 생산 목표(개) | H12: =가동율!AR5 -> 625.50657 | I12: =가동율!AR6 -> 742.98438 | J12: =가동율!AR7 -> 742.42532 | K12: =가동율!AR8 -> 800.13913 | L12: =가동율!AR9 -> 710.77973 | M12: =가동율!AR10 -> 746.5829 | N12: =가동율!AR11 -> 815.87513 | O12: =가동율!AR12 -> 737.93968 | P12: =가동율!AR13 -> 838.81098 | Q12: =가동율!AR14 -> 616.10085 | R12: =가동율!AR15 -> 742.896 | S12: =가동율!AR16 -> 752.52311 | T12: =SUM(H12:S12) -> 8872.5638
A13: 11 | B13: L12-13PT-3 | C13: ='1월'!AH18+'2월'!AH18+'3월'!AH18+'4월'!AH18+'5월'!AH18+'6월'!AH18+'7월'!AH18+'8월'!AH18+'9월'!AH18+'10월'!AH18+'11월'!AH18+'12월'!AH18 -> 0 | D13: ='1월'!AI18+'2월'!AI18+'3월'!AI18+'4월'!AI18+'5월'!AI18+'6월'!AI18+'7월'!AI18+'8월'!AI18+'9월'!AI18+'10월'!AI18+'11월'!AI18+'12월'!AI18 -> 0 | E13: =IFERROR(D13*100/C13,"0") -> 0 | G13: 월 생산 수(개) | H13: =H5 -> 533 | I13: =I5 -> 397 | J13: =J5 -> 695 | K13: =K5 -> 828 | L13: =L5 -> 809 | M13: =M5 -> 1006 | N13: =N5 -> 961 | O13: =O5 -> 862 | ... S13: =S5 -> 411 | T13: =SUM(H13:S13) -> 8425
A14: 12 | B14: L12-20PT-3 | C14: ='1월'!AH19+'2월'!AH19+'3월'!AH19+'4월'!AH19+'5월'!AH19+'6월'!AH19+'7월'!AH19+'8월'!AH19+'9월'!AH19+'10월'!AH19+'11월'!AH19+'12월'!AH19 -> 11 | D14: ='1월'!AI19+'2월'!AI19+'3월'!AI19+'4월'!AI19+'5월'!AI19+'6월'!AI19+'7월'!AI19+'8월'!AI19+'9월'!AI19+'10월'!AI19+'11월'!AI19+'12월'!AI19 -> 0 | E14: =IFERROR(D14*100/C14,"0") -> 0 | G14: 목표 달성 % | H14: =IFERROR(H13*100/H12,"0") -> 85.210936 | I14: =IFERROR(I13*100/I12,"0") -> 53.433155 | J14: =IFERROR(J13*100/J12,"0") -> 93.612109 | K14: =IFERROR(K13*100/K12,"0") -> 103.482 | L14: =IFERROR(L13*100/L12,"0") -> 113.81867 | M14: =IFERROR(M13*100/M12,"0") -> 134.74726 | N14: =IFERROR(N13*100/N12,"0") -> 117.78763 | O14: =IFERROR(O13*100/O12,"0") -> 116.81172 | ... T14: =IFERROR(T13*100/T12,"0") -> 94.955643
A15: 13 | B15: L12-40PT-3 | C15: ='1월'!AH20+'2월'!AH20+'3월'!AH20+'4월'!AH20+'5월'!AH20+'6월'!AH20+'7월'!AH20+'8월'!AH20+'9월'!AH20+'10월'!AH20+'11월'!AH20+'12월'!AH20 -> 346 | D15: ='1월'!AI20+'2월'!AI20+'3월'!AI20+'4월'!AI20+'5월'!AI20+'6월'!AI20+'7월'!AI20+'8월'!AI20+'9월'!AI20+'10월'!AI20+'11월'!AI20+'12월'!AI20 -> 1 | E15: =IFERROR(D15*100/C15,"0") -> 0.28901734 | G15: 인당 생산수/day | H15: =가동율!AT5 -> 16.274809 | I15: =가동율!AT6 -> 10.179487 | J15: =가동율!AT7 -> 17.820513 | K15: =가동율!AT8 -> 20.444444 | L15: =가동율!AT9 -> 22.472222 | M15: =가동율!AT10 -> 26.473684 | N15: =가동율!AT11 -> 22.880952 | O15: =가동율!AT12 -> 23.297297 | P15: =가동율!AT13 -> 20.704545 | Q15: =가동율!AT14 -> 18.34375 | R15: =가동율!AT15 -> 11.038961 | S15: =가동율!AT16 -> 10.606452 | T15: =AVERAGE(H15:S15) -> 18.378093
A16: 14 | B16: L12-64PT-3 | C16: ='1월'!AH21+'2월'!AH21+'3월'!AH21+'4월'!AH21+'5월'!AH21+'6월'!AH21+'7월'!AH21+'8월'!AH21+'9월'!AH21+'10월'!AH21+'11월'!AH21+'12월'!AH21 -> 0 | D16: ='1월'!AI21+'2월'!AI21+'3월'!AI21+'4월'!AI21+'5월'!AI21+'6월'!AI21+'7월'!AI21+'8월'!AI21+'9월'!AI21+'10월'!AI21+'11월'!AI21+'12월'!AI21 -> 0 | E16: =IFERROR(D16*100/C16,"0") -> 0 | G16: 인당 생산수 목표/day | H16: =가동율!AQ5 -> 19.099437 | I16: =가동율!AQ6 -> 19.050882 | J16: =가동율!AQ7 -> 19.036547 | K16: =가동율!AQ9 -> 19.743881 | L16: =가동율!AQ10 -> 19.646918 | M16: =가동율!AQ10 -> 19.646918 | N16: =가동율!AQ11 -> 19.425598 | O16: =가동율!AQ12 -> 19.944316 | P16: =가동율!AQ13 -> 19.063886 | Q16: =가동율!AQ14 -> 19.253152 | R16: =가동율!AQ15 -> 19.296 | S16: =가동율!AQ16 -> 19.419951 | T16: =AVERAGE(H16:S16) -> 19.385624
A17: 15 | B17: L12-100PT-3 | C17: ='1월'!AH22+'2월'!AH22+'3월'!AH22+'4월'!AH22+'5월'!AH22+'6월'!AH22+'7월'!AH22+'8월'!AH22+'9월'!AH22+'10월'!AH22+'11월'!AH22+'12월'!AH22 -> 0 | D17: ='1월'!AI22+'2월'!AI22+'3월'!AI22+'4월'!AI22+'5월'!AI22+'6월'!AI22+'7월'!AI22+'8월'!AI22+'9월'!AI22+'10월'!AI22+'11월'!AI22+'12월'!AI22 -> 0 | E17: =IFERROR(D17*100/C17,"0") -> 0 | G17: 목표UPH(개) | H17: =IFERROR((가동율!AR5/H7)/8,"0") -> 4.599313 | I17: =IFERROR((가동율!AR6/가동율!AM6)/8,"0") -> 4.6436524 | J17: =IFERROR((가동율!AR7/가동율!AM7)/8,"0") -> 4.6401583 | K17: =IFERROR((가동율!AR8/가동율!AM8)/8,"0") -> 4.5462451 | L17: =IFERROR((가동율!AR9/가동율!AM9)/8,"0") -> 4.9359703 | M17: =IFERROR((가동율!AR10/가동율!AM10)/8,"0") -> 4.9117296 | N17: =IFERROR((가동율!AR11/가동율!AM11)/8,"0") -> 4.8563996 | O17: =IFERROR((가동율!AR12/가동율!AM12)/8,"0") -> 4.8548663 | P17: =IFERROR((가동율!AR13/가동율!AM13)/8,"0") -> 4.7659715 | Q17: =IFERROR((가동율!AR14/가동율!AM14)/8,"0") -> 4.5301533 | R17: =IFERROR((가동율!AR15/가동율!AM15)/8,"0") -> 4.6431 | S17: =IFERROR((가동율!AR16/가동율!AM16)/8,"0") -> 4.4793043 | T17: =AVERAGE(H17:S17) -> 4.700572
A18: 16 | B18: L12-100PT-3MI | C18: ='1월'!AH23+'2월'!AH23+'3월'!AH23+'4월'!AH23+'5월'!AH23+'6월'!AH23+'7월'!AH23+'8월'!AH23+'9월'!AH23+'10월'!AH23+'11월'!AH23+'12월'!AH23 -> 302 | D18: ='1월'!AI23+'2월'!AI23+'3월'!AI23+'4월'!AI23+'5월'!AI23+'6월'!AI23+'7월'!AI23+'8월'!AI23+'9월'!AI23+'10월'!AI23+'11월'!AI23+'12월'!AI23 -> 1 | E18: =IFERROR(D18*100/C18,"0") -> 0.33112583 | G18: UPH(개) | H18: =H15*H10/8 -> 3.9191176 | I18: =I15*I10/8 -> 2.48125 | J18: =J15*J10/8 -> 4.34375 | K18: =K15*K10/8 -> 4.7045455 | L18: =L15*L10/8 -> 5.6180556 | M18: =M15*M10/8 -> 6.6184211 | N18: =N15*N10/8 -> 5.7202381 | O18: =O15*O10/8 -> 5.6710526 | ... S18: =S15*S10/8 -> 2.4464286 | T18: =AVERAGE(H18:O18) -> 4.8845538
A19: 17 | B19: L12-12F-3 | C19: ='1월'!AH24+'2월'!AH24+'3월'!AH24+'4월'!AH24+'5월'!AH24+'6월'!AH24+'7월'!AH24+'8월'!AH24+'9월'!AH24+'10월'!AH24+'11월'!AH24+'12월'!AH24 -> 1 | D19: ='1월'!AI24+'2월'!AI24+'3월'!AI24+'4월'!AI24+'5월'!AI24+'6월'!AI24+'7월'!AI24+'8월'!AI24+'9월'!AI24+'10월'!AI24+'11월'!AI24+'12월'!AI24 -> 0 | E19: =IFERROR(D19*100/C19,"0") -> 0 | G19: 목표 달성 % | H19: =IFERROR(H18*100/H17,"0") -> 85.210936 | I19: =IFERROR(I18*100/I17,"0") -> 53.433155 | J19: =IFERROR(J18*100/J17,"0") -> 93.612109 | K19: =IFERROR(K18*100/K17,"0") -> 103.482 | L19: =IFERROR(L18*100/L17,"0") -> 113.81867 | M19: =IFERROR(M18*100/M17,"0") -> 134.74726 | N19: =IFERROR(N18*100/N17,"0") -> 117.78763 | O19: =IFERROR(O18*100/O17,"0") -> 116.81172 | ... S19: =IFERROR(S18*100/S17,"0") -> 54.616263 | T19: =T18*100/T17 -> 103.91403
A20: 18 | B20: L12-20F-3 | C20: ='1월'!AH25+'2월'!AH25+'3월'!AH25+'4월'!AH25+'5월'!AH25+'6월'!AH25+'7월'!AH25+'8월'!AH25+'9월'!AH25+'10월'!AH25+'11월'!AH25+'12월'!AH25 -> 1841 | D20: ='1월'!AI25+'2월'!AI25+'3월'!AI25+'4월'!AI25+'5월'!AI25+'6월'!AI25+'7월'!AI25+'8월'!AI25+'9월'!AI25+'10월'!AI25+'11월'!AI25+'12월'!AI25 -> 10 | E20: =IFERROR(D20*100/C20,"0") -> 0.54318305 | G20: 월 별 직행 [%] | H20: =100-H6 -> 97.262774 | I20: =100-I6 -> 95.662651 | J20: =100-J6 -> 97.61236 | K20: =100-K6 -> 99.043062 | L20: =100-L6 -> 98.538368 | M20: =100-M6 -> 99.308983 | N20: =100-N6 -> 99.27686 | O20: =100-O6 -> 99.308756 | ... S20: =100-S6 -> 99.515738 | T20: =T5*100/T3 -> 98.653396
A21: 19 | B21: L12-40F-3 | C21: ='1월'!AH26+'2월'!AH26+'3월'!AH26+'4월'!AH26+'5월'!AH26+'6월'!AH26+'7월'!AH26+'8월'!AH26+'9월'!AH26+'10월'!AH26+'11월'!AH26+'12월'!AH26 -> 1058 | D21: ='1월'!AI26+'2월'!AI26+'3월'!AI26+'4월'!AI26+'5월'!AI26+'6월'!AI26+'7월'!AI26+'8월'!AI26+'9월'!AI26+'10월'!AI26+'11월'!AI26+'12월'!AI26 -> 8 | E21: =IFERROR(D21*100/C21,"0") -> 0.75614367 | G21: 직행 률 목표FPY[%] | H21: 97 | I21: =H21 -> 97 | J21: =H21 -> 97 | K21: =H21 -> 97 | L21: =H21 -> 97 | M21: =H21 -> 97 | N21: =H21 -> 97 | O21: =H21 -> 97 | P21: =H21 -> 97 | Q21: =H21 -> 97 | R21: =H21 -> 97 | S21: =H21 -> 97
A22: 20 | B22: L12-40F-3KL | C22: ='1월'!AH27+'2월'!AH27+'3월'!AH27+'4월'!AH27+'5월'!AH27+'6월'!AH27+'7월'!AH27+'8월'!AH27+'9월'!AH27+'10월'!AH27+'11월'!AH27+'12월'!AH27 -> 10 | D22: ='1월'!AI27+'2월'!AI27+'3월'!AI27+'4월'!AI27+'5월'!AI27+'6월'!AI27+'7월'!AI27+'8월'!AI27+'9월'!AI27+'10월'!AI27+'11월'!AI27+'12월'!AI27 -> 0 | E22: =IFERROR(D22*100/C22,"0") -> 0
A23: 21 | B23: L12-20PT-3EL | C23: ='1월'!AH28+'2월'!AH28+'3월'!AH28+'4월'!AH28+'5월'!AH28+'6월'!AH28+'7월'!AH28+'8월'!AH28+'9월'!AH28+'10월'!AH28+'11월'!AH28+'12월'!AH28 -> 0 | D23: ='1월'!AI28+'2월'!AI28+'3월'!AI28+'4월'!AI28+'5월'!AI28+'6월'!AI28+'7월'!AI28+'8월'!AI28+'9월'!AI28+'10월'!AI28+'11월'!AI28+'12월'!AI28 -> 0 | E23: =IFERROR(D23*100/C23,"0") -> 0
A24: 22 | B24: L12-64F-3 | C24: ='1월'!AH29+'2월'!AH29+'3월'!AH29+'4월'!AH29+'5월'!AH29+'6월'!AH29+'7월'!AH29+'8월'!AH29+'9월'!AH29+'10월'!AH29+'11월'!AH29+'12월'!AH29 -> 0 | D24: ='1월'!AI29+'2월'!AI29+'3월'!AI29+'4월'!AI29+'5월'!AI29+'6월'!AI29+'7월'!AI29+'8월'!AI29+'9월'!AI29+'10월'!AI29+'11월'!AI29+'12월'!AI29 -> 0 | E24: =IFERROR(D24*100/C24,"0") -> 0
A25: 23 | B25: L12-100F-3 | C25: ='1월'!AH30+'2월'!AH30+'3월'!AH30+'4월'!AH30+'5월'!AH30+'6월'!AH30+'7월'!AH30+'8월'!AH30+'9월'!AH30+'10월'!AH30+'11월'!AH30+'12월'!AH30 -> 213 | D25: ='1월'!AI30+'2월'!AI30+'3월'!AI30+'4월'!AI30+'5월'!AI30+'6월'!AI30+'7월'!AI30+'8월'!AI30+'9월'!AI30+'10월'!AI30+'11월'!AI30+'12월'!AI30 -> 3 | E25: =IFERROR(D25*100/C25,"0") -> 1.4084507
A26: 24 | B26: D7-6PT-3 | C26: ='1월'!AH31+'2월'!AH31+'3월'!AH31+'4월'!AH31+'5월'!AH31+'6월'!AH31+'7월'!AH31+'8월'!AH31+'9월'!AH31+'10월'!AH31+'11월'!AH31+'12월'!AH31 -> 10 | D26: ='1월'!AI31+'2월'!AI31+'3월'!AI31+'4월'!AI31+'5월'!AI31+'6월'!AI31+'7월'!AI31+'8월'!AI31+'9월'!AI31+'10월'!AI31+'11월'!AI31+'12월'!AI31 -> 0 | E26: =IFERROR(D26*100/C26,"0") -> 0
A27: 25 | B27: D7-6F-3 | C27: ='1월'!AH32+'2월'!AH32+'3월'!AH32+'4월'!AH32+'5월'!AH32+'6월'!AH32+'7월'!AH32+'8월'!AH32+'9월'!AH32+'10월'!AH32+'11월'!AH32+'12월'!AH32 -> 0 | D27: ='1월'!AI32+'2월'!AI32+'3월'!AI32+'4월'!AI32+'5월'!AI32+'6월'!AI32+'7월'!AI32+'8월'!AI32+'9월'!AI32+'10월'!AI32+'11월'!AI32+'12월'!AI32 -> 0 | E27: =IFERROR(D27*100/C27,"0") -> 0
A28: 26 | B28: D12-12PT-3 | C28: ='1월'!AH33+'2월'!AH33+'3월'!AH33+'4월'!AH33+'5월'!AH33+'6월'!AH33+'7월'!AH33+'8월'!AH33+'9월'!AH33+'10월'!AH33+'11월'!AH33+'12월'!AH33 -> 181 | D28: ='1월'!AI33+'2월'!AI33+'3월'!AI33+'4월'!AI33+'5월'!AI33+'6월'!AI33+'7월'!AI33+'8월'!AI33+'9월'!AI33+'10월'!AI33+'11월'!AI33+'12월'!AI33 -> 1 | E28: =IFERROR(D28*100/C28,"0") -> 0.55248619
A29: 27 | B29: D12-12F-3 | C29: ='1월'!AH34+'2월'!AH34+'3월'!AH34+'4월'!AH34+'5월'!AH34+'6월'!AH34+'7월'!AH34+'8월'!AH34+'9월'!AH34+'10월'!AH34+'11월'!AH34+'12월'!AH34 -> 71 | D29: ='1월'!AI34+'2월'!AI34+'3월'!AI34+'4월'!AI34+'5월'!AI34+'6월'!AI34+'7월'!AI34+'8월'!AI34+'9월'!AI34+'10월'!AI34+'11월'!AI34+'12월'!AI34 -> 0 | E29: =IFERROR(D29*100/C29,"0") -> 0
A30: 28 | B30: D12-6PT-3 | C30: ='1월'!AH35+'2월'!AH35+'3월'!AH35+'4월'!AH35+'5월'!AH35+'6월'!AH35+'7월'!AH35+'8월'!AH35+'9월'!AH35+'10월'!AH35+'11월'!AH35+'12월'!AH35 -> 40 | D30: ='1월'!AI35+'2월'!AI35+'3월'!AI35+'4월'!AI35+'5월'!AI35+'6월'!AI35+'7월'!AI35+'8월'!AI35+'9월'!AI35+'10월'!AI35+'11월'!AI35+'12월'!AI35 -> 0 | E30: =IFERROR(D30*100/C30,"0") -> 0
A31: 29 | B31: D12-6F-3 | C31: ='1월'!AH36+'2월'!AH36+'3월'!AH36+'4월'!AH36+'5월'!AH36+'6월'!AH36+'7월'!AH36+'8월'!AH36+'9월'!AH36+'10월'!AH36+'11월'!AH36+'12월'!AH36 -> 20 | D31: ='1월'!AI36+'2월'!AI36+'3월'!AI36+'4월'!AI36+'5월'!AI36+'6월'!AI36+'7월'!AI36+'8월'!AI36+'9월'!AI36+'10월'!AI36+'11월'!AI36+'12월'!AI36 -> 0 | E31: =IFERROR(D31*100/C31,"0") -> 0
A32: 30 | B32: D7-12PT-3 | C32: ='1월'!AH37+'2월'!AH37+'3월'!AH37+'4월'!AH37+'5월'!AH37+'6월'!AH37+'7월'!AH37+'8월'!AH37+'9월'!AH37+'10월'!AH37+'11월'!AH37+'12월'!AH37 -> 10 | D32: ='1월'!AI37+'2월'!AI37+'3월'!AI37+'4월'!AI37+'5월'!AI37+'6월'!AI37+'7월'!AI37+'8월'!AI37+'9월'!AI37+'10월'!AI37+'11월'!AI37+'12월'!AI37 -> 0 | E32: =IFERROR(D32*100/C32,"0") -> 0
A33: 31 | B33: D7-12F-3 | C33: ='1월'!AH38+'2월'!AH38+'3월'!AH38+'4월'!AH38+'5월'!AH38+'6월'!AH38+'7월'!AH38+'8월'!AH38+'9월'!AH38+'10월'!AH38+'11월'!AH38+'12월'!AH38 -> 0 | D33: ='1월'!AI38+'2월'!AI38+'3월'!AI38+'4월'!AI38+'5월'!AI38+'6월'!AI38+'7월'!AI38+'8월'!AI38+'9월'!AI38+'10월'!AI38+'11월'!AI38+'12월'!AI38 -> 0 | E33: =IFERROR(D33*100/C33,"0") -> 0
... A182: 180 | B182: IR-CT01 | C182: ='1월'!AH187+'2월'!AH187+'3월'!AH187+'4월'!AH187+'5월'!AH187+'6월'!AH187+'7월'!AH187+'8월'!AH187+'9월'!AH187+'10월'!AH187+'11월'!AH187+'12월'!AH187 -> 0 | D182: ='1월'!AI187+'2월'!AI187+'3월'!AI187+'4월'!AI187+'5월'!AI187+'6월'!AI187+'7월'!AI187+'8월'!AI187+'9월'!AI187+'10월'!AI187+'11월'!AI187+'12월'!AI187 -> 0 | E182: =IFERROR(D182*100/C182,"0") -> 0
C183: =SUM(C3:C182) -> 8540 | D183: =SUM(D3:D182) -> 115 | E183: =D183/C183 -> 0.013466042

Sheet Model별 생산현황1
B1: Model | C1: 검사 수[EA] | D1: 불량 수[EA] | E1: 양품 수[EA] | F1: 점유 % | G1: 불량% | I1: 검사 수 | J1: 불량 수 | K1: 양품수(생산수) | L1: 불량%
B2: L12-20F-3 | C2: =VLOOKUP(B2,'생산 현황'!$B$2:$E$182,2,0) -> 1841 | D2: =VLOOKUP(B2,'생산 현황'!$B$2:$E$182,3,0) -> 10 | E2: =C2-D2 -> 1831 | F2: =IFERROR(E2*100/$K$2,"0") -> 21.732938 | G2: =IFERROR(D2*100/C2,"0") -> 0.54318305 | I2: =SUM(C2:C175) -> 8540 | J2: =SUM(D2:D175) -> 115 | K2: =I2-J2 -> 8425 | L2: =IFERROR((J2*100/I2),"0") -> 1.3466042
B3: L12-40F-3 | C3: =VLOOKUP(B3,'생산 현황'!$B$2:$E$182,2,0) -> 1058 | D3: =VLOOKUP(B3,'생산 현황'!$B$2:$E$182,3,0) -> 8 | E3: =C3-D3 -> 1050 | F3: =IFERROR(E3*100/$K$2,"0") -> 12.462908 | G3: =IFERROR(D3*100/C3,"0") -> 0.75614367
B4: 12Lf-12F-27 | C4: =VLOOKUP(B4,'생산 현황'!$B$2:$E$182,2,0) -> 619 | D4: =VLOOKUP(B4,'생산 현황'!$B$2:$E$182,3,0) -> 5 | E4: =C4-D4 -> 614 | F4: =IFERROR(E4*100/$K$2,"0") -> 7.2878338 | G4: =IFERROR(D4*100/C4,"0") -> 0.80775444
B5: L12-20PT-3ES | C5: =VLOOKUP(B5,'생산 현황'!$B$2:$E$182,2,0) -> 426 | D5: =VLOOKUP(B5,'생산 현황'!$B$2:$E$182,3,0) -> 4 | E5: =C5-D5 -> 422 | F5: =IFERROR(E5*100/$K$2,"0") -> 5.0089021 | G5: =IFERROR(D5*100/C5,"0") -> 0.93896714
B6: 12Lf-100F-27 | C6: =VLOOKUP(B6,'생산 현황'!$B$2:$E$182,2,0) -> 386 | D6: =VLOOKUP(B6,'생산 현황'!$B$2:$E$182,3,0) -> 6 | E6: =C6-D6 -> 380 | F6: =IFERROR(E6*100/$K$2,"0") -> 4.5103858 | G6: =IFERROR(D6*100/C6,"0") -> 1.5544041
B7: L12-40PT-3 | C7: =VLOOKUP(B7,'생산 현황'!$B$2:$E$182,2,0) -> 346 | D7: =VLOOKUP(B7,'생산 현황'!$B$2:$E$182,3,0) -> 1 | E7: =C7-D7 -> 345 | F7: =IFERROR(E7*100/$K$2,"0") -> 4.0949555 | G7: =IFERROR(D7*100/C7,"0") -> 0.28901734
B8: L12-100PT-3MI | C8: =VLOOKUP(B8,'생산 현황'!$B$2:$E$182,2,0) -> 302 | D8: =VLOOKUP(B8,'생산 현황'!$B$2:$E$182,3,0) -> 1 | E8: =C8-D8 -> 301 | F8: =IFERROR(E8*100/$K$2,"0") -> 3.5727003 | G8: =IFERROR(D8*100/C8,"0") -> 0.33112583
B9: L12-100F-3 | C9: =VLOOKUP(B9,'생산 현황'!$B$2:$E$182,2,0) -> 213 | D9: =VLOOKUP(B9,'생산 현황'!$B$2:$E$182,3,0) -> 3 | E9: =C9-D9 -> 210 | F9: =IFERROR(E9*100/$K$2,"0") -> 2.4925816 | G9: =IFERROR(D9*100/C9,"0") -> 1.4084507
B10: L12-80F-4 | C10: =VLOOKUP(B10,'생산 현황'!$B$2:$E$182,2,0) -> 207 | D10: =VLOOKUP(B10,'생산 현황'!$B$2:$E$182,3,0) -> 9 | E10: =C10-D10 -> 198 | F10: =IFERROR(E10*100/$K$2,"0") -> 2.3501484 | G10: =IFERROR(D10*100/C10,"0") -> 4.3478261
B11: D12-12PT-3 | C11: =VLOOKUP(B11,'생산 현황'!$B$2:$E$182,2,0) -> 181 | D11: =VLOOKUP(B11,'생산 현황'!$B$2:$E$182,3,0) -> 1 | E11: =C11-D11 -> 180 | F11: =IFERROR(E11*100/$K$2,"0") -> 2.1364985 | G11: =IFERROR(D11*100/C11,"0") -> 0.55248619
B12: 12Lf-78F-53 | C12: =VLOOKUP(B12,'생산 현황'!$B$2:$E$182,2,0) -> 159 | D12: =VLOOKUP(B12,'생산 현황'!$B$2:$E$182,3,0) -> 0 | E12: =C12-D12 -> 159 | F12: =IFERROR(E12*100/$K$2,"0") -> 1.8872404 | G12: =IFERROR(D12*100/C12,"0") -> 0
B13: 12Lf-35F-27 | C13: =VLOOKUP(B13,'생산 현황'!$B$2:$E$182,2,0) -> 160 | D13: =VLOOKUP(B13,'생산 현황'!$B$2:$E$182,3,0) -> 1 | E13: =C13-D13 -> 159 | F13: =IFERROR(E13*100/$K$2,"0") -> 1.8872404 | G13: =IFERROR(D13*100/C13,"0") -> 0.625
B14: 12Lf-20PT-27 | C14: =VLOOKUP(B14,'생산 현황'!$B$2:$E$182,2,0) -> 150 | D14: =VLOOKUP(B14,'생산 현황'!$B$2:$E$182,3,0) -> 3 | E14: =C14-D14 -> 147 | F14: =IFERROR(E14*100/$K$2,"0") -> 1.7448071 | G14: =IFERROR(D14*100/C14,"0") -> 2
... B181: IR-CT01 | C181: =VLOOKUP(B181,'생산 현황'!$B$2:$E$182,2,0) -> 0 | D181: =VLOOKUP(B181,'생산 현황'!$B$2:$E$182,3,0) -> 0 | E181: =C181-D181 -> 0 | F181: =IFERROR(E181*100/$K$2,"0") -> 0 | G181: =IFERROR(D181*100/C181,"0") -> 0

Sheet 가동율
AP1: ※양품(검사 합격품) 기준
B2: Time | AJ2: Standard | AS2: 실적
B3: 월/일 | C3: 1 | D3: 2 | E3: 3 | F3: 4 | G3: 5 | H3: 6 | I3: 7 | J3: 8 | K3: 9 | L3: 10 | M3: 11 | N3: 12 | O3: 13 | P3: 14 | Q3: 15 | R3: 16 | S3: 17 | T3: 18 | U3: 19 | V3: 20 | W3: 21 | X3: 22 | Y3: 23 | Z3: 24 | AA3: 25 | AB3: 26 | AC3: 27 | AD3: 28 | AE3: 29 | AF3: 30 | AG3: 31 | AH3: 작업 시간[H] | AI3: 월/항목 | AJ3: 보유 Capa/월(人) | AK3: 유효 Capa/월(人) | AL3: 일일 평균/일(人) | AM3: 작업 일수/day | AN3: 가동% | AO3: 표준 UPH | AP3: UPH (표준/1인) | AQ3: 일일목표 생산수/1인(Qty) | AR3: 월 목표 생산수(Qty) | AS3: 월 실적/Qty | AT3: 일일 인당 생산수(Qty) | AU3: UPH (생산/월) | AV3: UPH (1인/생산) | AW3: 불량% | AX3: 생산 결과 (Qty) | AY3: 목표 달성% | AZ3: 누적 수량(Qty) | BA3: 생산 CAPA 여유 % | BB3: 목표 미달성 원인 | BC3: 비가동 원인
B5: 1 | D5: 2 | E5: 2 | H5: 2 | I5: 2 | J5: 2 | K5: 2 | L5: 2 | O5: 1 | P5: 2 | Q5: 2 | R5: 2 | S5: 2 | V5: 2 | W5: 2 | X5: 1.75 | Y5: 2 | Z5: 2 | AH5: =AM5*8 -> 136 | AI5: 1 | AJ5: =AM5*2 -> 34 | AK5: =SUM(C5:AG5) -> 32.75 | AL5: =IFERROR(AVERAGE(C5:AG5),"0") -> 1.9264706 | AM5: =COUNTA(C5:AG5) -> 17 | AN5: =IFERROR(AK5*100/AJ5,"0") -> 96.323529 | AO5: =AP5*AL5 -> 4.599313 | AP5: ='1월'!$X$106 -> 2.3874296 | AQ5: ='1월'!X106*8 -> 19.099437 | AR5: =AQ5*AL5*AM5 -> 625.50657 | AS5: ='월 품질 현황'!C6 -> 533 | AT5: =IFERROR(AS5/AK5,"0") -> 16.274809 | AU5: ='1월'!R3 -> 3.9191176 | AV5: =IFERROR(AU5/AL5,"0") -> 2.0343511 | AW5: ='월 품질 현황'!C5 -> 2.7372263 | AX5: =AS5-AR5 -> -92.506567 | AY5: =IFERROR(AS5*100/AR5,"0") -> 85.210936 | AZ5: =AX5 -> -92.506567 | BA5: =IFERROR((AR5-AS5)*100/AR5,"0") -> 14.789064 | BC5: 휴가
